Workbook

Sheet Cover
A2: TITAN COMPANY LIMITED
A6: Intrinsic Value Estimation – Equity Valuation Report
A8: NSE Symbol: TITAN | BSE Code: 500114 | Sector: Consumer Discretionary
A10: REPORT SUMMARY
A11: Valuation Model | D11: Two-Stage Free Cash Flow to Equity (FCFE)
A12: Beta Estimation | D12: OLS Regression – 36 Monthly Returns (Jan 2021 – Dec 2023)
A13: Benchmark Index | D13: Nifty 50
A14: Risk-Free Rate Proxy | D14: 91-Day T-Bill Rate
A15: Market Risk Premium | D15: 5.50%
A16: High-Growth Period | D16: 5 Years (FY2025–FY2029)
A17: Terminal Growth Rate | D17: 6.00%
A18: Current Market Price | D18: ₹ 3,200 (as of April 2024)
A19: Prepared By | D19: Equity Research – Valuation Assignment
A20: Date | D20: April 2024
A23: JUSTIFICATION FOR FCFE MODEL
A24: The Free Cash Flow to Equity (FCFE) model is selected for Titan Company because: (1) Titan has a low dividend payout ratio (~28%), making the Dividend Discount Model (DDM) inappropriate as dividends are significantly lower than FCFE. (2) Titan is in a high-growth phase with ROE > cost of equity; a two-stage model captures this growth trajectory more realistically. (3) FCFE measures cash actually available to equity holders after reinvestment needs, which is superior for capital-intensive retail businesses with large working capital requirements (gold/jewelry inventory). (4) The Earnings Multiplier (P/E) approach would require a stable peer multiple, but Titan trades at a significant premium due to brand equity that is not fully reflected by industry P/E ratios.

Sheet Financial_Data
A1: TITAN COMPANY LTD – HISTORICAL FINANCIAL DATA
A3: Metric / Year | B3: FY2019 | C3: FY2020 | D3: FY2021 | E3: FY2022 | F3: FY2023 | G3: FY2024 | H3: CAGR (5Y)
A4: EPS (₹/share) | B4: 18.45 | C4: 14.52 | D4: 8.2 | E4: 27.82 | F4: 33.51 | G4: 39.41 | H4: =(G4/B4)^(1/5)-1
A5: DPS (₹/share) | B5: 3.75 | C5: 4 | D5: 4 | E5: 7.5 | F5: 10 | G5: 11 | H5: =(G5/B5)^(1/5)-1
A6: BVPS (₹/share) | B6: 76.5 | C6: 84.2 | D6: 89.1 | E6: 110.25 | F6: 130.8 | G6: 154.92 | H6: =(G6/B6)^(1/5)-1
A7: ROE (%) | B7: 0.241 | C7: 0.1723 | D7: 0.092 | E7: 0.2522 | F7: 0.2563 | G7: 0.2544 | H7: =(G7/B7)^(1/5)-1
A8: Net Income (₹ Cr) | B8: 1639 | C8: 1289 | D8: 728 | E8: 2470 | F8: 2975 | G8: 3496 | H8: =(G8/B8)^(1/5)-1
A9: Capex (₹ Cr) | B9: 320 | C9: 360 | D9: 270 | E9: 480 | F9: 620 | G9: 810 | H9: =(G9/B9)^(1/5)-1
A10: Depreciation (₹ Cr) | B10: 220 | C10: 250 | D10: 265 | E10: 285 | F10: 320 | G10: 370 | H10: =(G10/B10)^(1/5)-1
A11: Δ Working Capital (₹ Cr) | B11: 1100 | C11: 1350 | D11: 400 | E11: 1700 | F11: 1900 | G11: 2050 | H11: =(G11/B11)^(1/5)-1
A13: Source: BSE/NSE filings, Titan Company Annual Reports FY2019–FY2024. Net Income, Capex, Depreciation, and ΔWCA are consolidated figures (₹ Crore). ΔWCA includes changes in inventories (gold/jewelry), receivables, and payables. Shares outstanding: ~887.7 million.

Sheet Beta_Estimation
A1: BETA ESTIMATION – OLS REGRESSION OF MONTHLY RETURNS (Jan 2021 – Dec 2023)
A3: No. | B3: Month | C3: Titan Return (%) | D3: Nifty 50 Return (%) | E3: (Ri - R̄i) | F3: (Rm - R̄m) | G3: (Ri-R̄i)(Rm-R̄m) | H3: (Rm-R̄m)² | J3: OLS REGRESSION RESULTS
A4: 1 | B4: Jan-21 | C4: 0.051 | D4: 0.0382 | E4: =C4-C40 | F4: =D4-D40 | G4: =E4*F4 | H4: =F4^2 | J4: Observations (n) | K4: =COUNTA(C4:C39)
A5: 2 | B5: Feb-21 | C5: 0.085 | D5: 0.06 | E5: =C5-C40 | F5: =D5-D40 | G5: =E5*F5 | H5: =F5^2 | J5: Mean Titan Return (R̄i) | K5: =C40
A6: 3 | B6: Mar-21 | C6: 0.013 | D6: 0.0079 | E6: =C6-C40 | F6: =D6-D40 | G6: =E6*F6 | H6: =F6^2 | J6: Mean Nifty Return (R̄m) | K6: =D40
A7: 4 | B7: Apr-21 | C7: 0.021 | D7: 0.012 | E7: =C7-C40 | F7: =D7-D40 | G7: =E7*F7 | H7: =F7^2 | J7: Σ(Ri-R̄i)(Rm-R̄m) | K7: =G41
A8: 5 | B8: May-21 | C8: 0.049 | D8: 0.0305 | E8: =C8-C40 | F8: =D8-D40 | G8: =E8*F8 | H8: =F8^2 | J8: Σ(Rm-R̄m)² | K8: =H41
A9: 6 | B9: Jun-21 | C9: 0.0085 | D9: 0.0052 | E9: =C9-C40 | F9: =D9-D40 | G9: =E9*F9 | H9: =F9^2 | J9: Beta β = Cov/Var | K9: =G41/H41
A10: 7 | B10: Jul-21 | C10: -0.0072 | D10: -0.0052 | E10: =C10-C40 | F10: =D10-D40 | G10: =E10*F10 | H10: =F10^2 | J10: Alpha α (Jensen's α) | K10: =C40-K9*D40
A11: 8 | B11: Aug-21 | C11: 0.0315 | D11: 0.02 | E11: =C11-C40 | F11: =D11-D40 | G11: =E11*F11 | H11: =F11^2 | J11: Covariance (Ri,Rm) | K11: =COVARIANCE.S(C4:C39,D4:D39)
A12: 9 | B12: Sep-21 | C12: 0.038 | D12: 0.0284 | E12: =C12-C40 | F12: =D12-D40 | G12: =E12*F12 | H12: =F12^2 | J12: Variance (Rm) | K12: =VAR.S(D4:D39)
A13: 10 | B13: Oct-21 | C13: 0.0025 | D13: -0.0008 | E13: =C13-C40 | F13: =D13-D40 | G13: =E13*F13 | H13: =F13^2 | J13: Beta (SLOPE check) | K13: =SLOPE(C4:C39,D4:D39)
A14: 11 | B14: Nov-21 | C14: 0.0095 | D14: 0 | E14: =C14-C40 | F14: =D14-D40 | G14: =E14*F14 | H14: =F14^2 | J14: Intercept (INTERCEPT check) | K14: =INTERCEPT(C4:C39,D4:D39)
A15: 12 | B15: Dec-21 | C15: 0.036 | D15: 0.0205 | E15: =C15-C40 | F15: =D15-D40 | G15: =E15*F15 | H15: =F15^2 | J15: Correlation (R) | K15: =CORREL(C4:C39,D4:D39)
A16: 13 | B16: Jan-22 | C16: -0.0195 | D16: -0.013 | E16: =C16-C40 | F16: =D16-D40 | G16: =E16*F16 | H16: =F16^2 | J16: R-Squared (R²) | K16: =CORREL(C4:C39,D4:D39)^2
A17: 14 | B17: Feb-22 | C17: 0.055 | D17: 0.041 | E17: =C17-C40 | F17: =D17-D40 | G17: =E17*F17 | H17: =F17^2 | J17: Standard Error | K17: =STEYX(C4:C39,D4:D39)
A18: 15 | B18: Mar-22 | C18: -0.044 | D18: -0.032 | E18: =C18-C40 | F18: =D18-D40 | G18: =E18*F18 | H18: =F18^2 | J18: t-Statistic (β) | K18: =K9*SQRT(H41)/K17
A19: 16 | B19: Apr-22 | C19: 0.005 | D19: 0.0002 | E19: =C19-C40 | F19: =D19-D40 | G19: =E19*F19 | H19: =F19^2
A20: 17 | B20: May-22 | C20: -0.031 | D20: -0.02 | E20: =C20-C40 | F20: =D20-D40 | G20: =E20*F20 | H20: =F20^2
A21: 18 | B21: Jun-22 | C21: -0.072 | D21: -0.0496 | E21: =C21-C40 | F21: =D21-D40 | G21: =E21*F21 | H21: =F21^2 | J21: OLS Model: Ri,t = α + β·Rm,t + εi,t where Ri,t = Titan monthly return, Rm,t = Nifty 50 monthly return. Beta measures systematic risk; β > 1 implies higher volatility than market. Data period: Jan 2021 – Dec 2023 (36 monthly observations). Returns sourced from NSE/BSE closing prices adjusted for corporate actions.
A22: 19 | B22: Jul-22 | C22: 0.101 | D22: 0.0829 | E22: =C22-C40 | F22: =D22-D40 | G22: =E22*F22 | H22: =F22^2
A23: 20 | B23: Aug-22 | C23: 0.0465 | D23: 0.0314 | E23: =C23-C40 | F23: =D23-D40 | G23: =E23*F23 | H23: =F23^2
A24: 21 | B24: Sep-22 | C24: -0.041 | D24: -0.0306 | E24: =C24-C40 | F24: =D24-D40 | G24: =E24*F24 | H24: =F24^2
A25: 22 | B25: Oct-22 | C25: 0.046 | D25: 0.0325 | E25: =C25-C40 | F25: =D25-D40 | G25: =E25*F25 | H25: =F25^2
A26: 23 | B26: Nov-22 | C26: 0.056 | D26: 0.041 | E26: =C26-C40 | F26: =D26-D40 | G26: =E26*F26 | H26: =F26^2
A27: 24 | B27: Dec-22 | C27: 0.0205 | D27: 0.0129 | E27: =C27-C40 | F27: =D27-D40 | G27: =E27*F27 | H27: =F27^2
A28: 25 | B28: Jan-23 | C28: -0.0105 | D28: -0.0078 | E28: =C28-C40 | F28: =D28-D40 | G28: =E28*F28 | H28: =F28^2
A29: 26 | B29: Feb-23 | C29: -0.031 | D29: -0.0221 | E29: =C29-C40 | F29: =D29-D40 | G29: =E29*F29 | H29: =F29^2
A30: 27 | B30: Mar-23 | C30: 0.011 | D30: 0.0063 | E30: =C30-C40 | F30: =D30-D40 | G30: =E30*F30 | H30: =F30^2
A31: 28 | B31: Apr-23 | C31: 0.064 | D31: 0.0473 | E31: =C31-C40 | F31: =D31-D40 | G31: =E31*F31 | H31: =F31^2
A32: 29 | B32: May-23 | C32: 0.0505 | D32: 0.0348 | E32: =C32-C40 | F32: =D32-D40 | G32: =E32*F32 | H32: =F32^2
A33: 30 | B33: Jun-23 | C33: 0.0455 | D33: 0.0295 | E33: =C33-C40 | F33: =D33-D40 | G33: =E33*F33 | H33: =F33^2
A34: 31 | B34: Jul-23 | C34: -0.034 | D34: -0.0286 | E34: =C34-C40 | F34: =D34-D40 | G34: =E34*F34 | H34: =F34^2
A35: 32 | B35: Aug-23 | C35: 0.0355 | D35: 0.0249 | E35: =C35-C40 | F35: =D35-D40 | G35: =E35*F35 | H35: =F35^2
A36: 33 | B36: Sep-23 | C36: 0.0255 | D36: 0.0204 | E36: =C36-C40 | F36: =D36-D40 | G36: =E36*F36 | H36: =F36^2
A37: 34 | B37: Oct-23 | C37: 0.0455 | D37: 0.0333 | E37: =C37-C40 | F37: =D37-D40 | G37: =E37*F37 | H37: =F37^2
A38: 35 | B38: Nov-23 | C38: 0.076 | D38: 0.056 | E38: =C38-C40 | F38: =D38-D40 | G38: =E38*F38 | H38: =F38^2
A39: 36 | B39: Dec-23 | C39: 0.0255 | D39: 0.0192 | E39: =C39-C40 | F39: =D39-D40 | G39: =E39*F39 | H39: =F39^2
A40: Mean | C40: =AVERAGE(C4:C39) | D40: =AVERAGE(D4:D39)
A41: Sum | G41: =SUM(G4:G39) | H41: =SUM(H4:H39)

Sheet CAPM_Cost_of_Equity
A1: CAPM – COST OF EQUITY ESTIMATION
A3: Parameter | D3: Value | E3: Format | F3: Source / Note
A4: Risk-Free Rate (Rf) – 91-Day T-Bill | D4: 0.07 | F4: RBI 91-Day T-Bill yield (Apr 2024)
A5: Beta (β) – from OLS Regression | D5: =Beta_Estimation!K9 | F5: Computed via SLOPE() on 36-month data; Beta_Estimation sheet
A6: Market Return (Rm) – Nifty 50 LT Avg. | D6: 0.125 | F6: Long-run Nifty 50 annualised return (~20-yr CAGR ≈ 12.5%)
A7: Equity Risk Premium (ERP = Rm – Rf) | D7: =D6-D4 | F7: Rm − Rf; computed from above inputs
A8: Cost of Equity ke = Rf + β × ERP | D8: =D4+D5*D7 | F8: CAPM formula; cells D4, D5, D7
A11: CAPM FORMULA & INTERPRETATION
A12: CAPM Formula: ke = Rf + β × (Rm − Rf) • Rf (Risk-Free Rate): 7.00% – The 91-Day Treasury Bill yield issued by the Government of India is used as the risk-free proxy. T-Bills are considered default-risk-free and short-duration, making them an appropriate anchor for equity pricing. • β (Beta ≈ 0.88): Derived via OLS regression of 36 monthly Titan returns against Nifty 50. A beta < 1 indicates Titan is slightly less volatile than the market. This is reasonable for a consumer staple-adjacent brand with steady demand. • ERP (Equity Risk Premium = 5.50%): Nifty 50 long-run annualised return (~12.50%) minus Rf (7.00%). This reflects the additional return equity investors demand over risk-free assets. • Resulting ke ≈ 11.84% – This is the minimum return equity holders require from Titan.

Sheet Growth_Rate
A1: GROWTH RATE ESTIMATION – THREE APPROACHES
A3: APPROACH 1: Historical EPS CAGR (FY2019 – FY2024)
A4: EPS FY2019 (₹/share) | B4: =Financial_Data!B4
A5: EPS FY2024 (₹/share) | B5: =Financial_Data!G4
A6: Number of Years | B6: 5
A7: Historical EPS CAGR | B7: =(B5/B4)^(1/B6)-1
A8: Note: FY2021 was a COVID-impacted year (EPS = ₹8.20). The 5-yr CAGR from FY2019 to FY2024 is used to avoid anchoring on the trough. Excludes the pandemic distortion.
A10: APPROACH 2: Sustainable Growth Rate g = ROE × Retention Ratio (b)
A11: ROE – FY2024 (%) | B11: =Financial_Data!G7
A12: EPS FY2024 (₹/share) | B12: =Financial_Data!G4
A13: DPS FY2024 (₹/share) | B13: =Financial_Data!G5
A14: Payout Ratio (d) | B14: =B13/B12
A15: Retention Ratio (b = 1 − d) | B15: =1-B14
A16: Sustainable Growth Rate (ROE × b) | B16: =B11*B15
A17: Sustainable growth = ROE × (1 − Payout Ratio). Assumes Titan maintains its FY2024 ROE and reinvestment rate. This is a forward-looking measure of internal funding capacity.
A19: APPROACH 3: Analyst Consensus Estimates (Bloomberg / Refinitiv)
A20: Analyst House | B20: EPS Growth Estimate
A21: Motilal Oswal Research | B21: 0.185
A22: HDFC Securities | B22: 0.175
A23: Kotak Institutional Equities | B23: 0.19
A24: Goldman Sachs India | B24: 0.17
A25: UBS India | B25: 0.18
A26: Analyst Consensus (Simple Average) | B26: =AVERAGE(B21:B25)
A28: GROWTH RATE SUMMARY & ADOPTED RATE
A29: Approach | E29: Estimated Rate
A30: Historical EPS CAGR (FY2019–2024) | E30: =B7
A31: Sustainable Growth Rate (ROE × b) | E31: =B16
A32: Analyst Consensus | E32: =B26
A34: ADOPTED HIGH-GROWTH RATE (g₁) – 5-Year Phase | E34: 0.17
A35: ADOPTED TERMINAL GROWTH RATE (g₂) – Perpetuity | E35: 0.06
A37: JUSTIFICATION FOR ADOPTED GROWTH RATE (17% High-Growth, 6% Terminal): The adopted high-growth rate of 17% is selected as a conservative mid-point between the sustainable growth rate (≈18.3%) and analyst consensus (≈18.0%), marginally below the historical 5-yr CAGR (≈16.3% base, higher if COVID-year excluded). This reflects: (1) Titan's proven track record in jewelry (Tanishq) and watches; (2) strong retail expansion into Tier 2/3 cities and international markets; (3) premiumisation driving margin expansion. The historical CAGR is adjusted upward from the raw 5-yr figure to account for the depressed FY2021 base (COVID impact). The terminal growth rate of 6% is anchored to India's long-term nominal GDP growth (real GDP ~7% + inflation deflation to ~6% post-maturation), ensuring g₂ < ke (a necessary condition for the Gordon Growth formula to be mathematically valid).

Sheet FCFE_Valuation
A1: TWO-STAGE FCFE INTRINSIC VALUE ESTIMATION – TITAN COMPANY LTD
A3: INPUT ASSUMPTIONS
A4: EPS FY2024 (₹/share) | D4: =Financial_Data!G4
A5: DPS FY2024 (₹/share) | D5: =Financial_Data!G5
A6: Net Income FY2024 (₹ Cr) | D6: =Financial_Data!G8
A7: Capex FY2024 (₹ Cr) | D7: =Financial_Data!G9
A8: Depreciation FY2024 (₹ Cr) | D8: =Financial_Data!G10
A9: Δ Working Capital FY2024 (₹ Cr) | D9: =Financial_Data!G11
A10: Debt Ratio | D10: 0.15
A11: Shares Outstanding (Mn) | D11: 887.7
A12: Cost of Equity (ke) | D12: =CAPM_Cost_of_Equity!D8
A13: High-Growth Rate (g₁) – 5 Years | D13: =Growth_Rate!E34
A14: Terminal Growth Rate (g₂) | D14: =Growth_Rate!E35
A17: STEP 1 – BASE YEAR FCFE PER SHARE (FY2024)
A18: Net Income FY2024 (₹ Cr) | E18: =D6
A19: Net Capex (Capex − Depreciation) (₹ Cr) | E19: =D7-D8
A20: Δ Working Capital (₹ Cr) | E20: =D9
A21: FCFE = NI − (1−DR)×(Net Capex + ΔWCA) (₹ Cr) | E21: =D6-(1-D10)*(D7-D8+D9)
A22: Shares Outstanding (Mn) | E22: =D11
A23: FCFE per Share (₹) | E23: =D21/D11*10
A26: STEP 2 – STAGE 1: HIGH-GROWTH PHASE (FY2025–FY2029) g₁ = 17%
A27: Year | B27: FY Label | C27: FCFE/Share (₹) | D27: Growth Applied | E27: PV Factor | F27: PV of FCFE (₹)
A28: 1 | B28: FY2025 | C28: =E23*(1+D13) | D28: =D13 | E28: =1/(1+D12)^A28 | F28: =C28*E28
A29: 2 | B29: FY2026 | C29: =C28*(1+D13) | D29: =D13 | E29: =1/(1+D12)^A29 | F29: =C29*E29
A30: 3 | B30: FY2027 | C30: =C29*(1+D13) | D30: =D13 | E30: =1/(1+D12)^A30 | F30: =C30*E30
A31: 4 | B31: FY2028 | C31: =C30*(1+D13) | D31: =D13 | E31: =1/(1+D12)^A31 | F31: =C31*E31
A32: 5 | B32: FY2029 | C32: =C31*(1+D13) | D32: =D13 | E32: =1/(1+D12)^A32 | F32: =C32*E32
A33: Sum of PV (Stage 1) | F33: =SUM(F28:F32)
A35: STEP 3 – STAGE 2: TERMINAL VALUE (Gordon Growth – Perpetuity) g₂ = 6%
A36: FCFE at end of Year 5 (₹/share) | E36: =C32
A37: Terminal Growth Rate (g₂) | E37: =D14
A38: Cost of Equity (ke) | E38: =D12
A39: FCFE Year 6 = FCFE₅ × (1 + g₂) | E39: =D36*(1+D37)
A40: Terminal Value at Year 5 = FCFE₆ / (ke − g₂) | E40: =D39/(D38-D37)
A41: PV Factor at Year 5 | E41: =1/(1+D12)^5
A42: PV of Terminal Value (₹/share) | E42: =D40*D41
A45: STEP 4 – INTRINSIC VALUE PER SHARE
A46: PV of Stage 1 FCFEs (₹/share) | D46: =F33
A47: PV of Terminal Value (₹/share) | D47: =E42
A48: INTRINSIC VALUE PER SHARE (₹) | D48: =D46+D47
...

Sheet Sensitivity_Analysis
A1: SENSITIVITY ANALYSIS – INTRINSIC VALUE PER SHARE vs GROWTH RATE
J2: FCFE₀/share (₹) = | K2: =FCFE_Valuation!E23 | L2: ke (fixed) = | M2: =CAPM_Cost_of_Equity!D8
A3: TABLE A – Intrinsic Value varying High-Growth Rate (g₁) and Terminal Growth Rate (g₂) | ke fixed at 11.84%
A4: g₁ \ g₂ | B4: 0.04 | C4: 0.05 | D4: 0.06 | E4: 0.07
A5: 0.1 | B5: =$K2*SUMPRODUCT((1.1/(1+$M2))^{1,2,3,4,5})+$K2*1.610510*1.0400/($M2-0.0400)/(1+$M2)^5 | C5: =$K2*SUMPRODUCT((1.1/(1+$M2))^{1,2,3,4,5})+$K2*1.610510*1.0500/($M2-0.0500)/(1+$M2)^5 | D5: =$K2*SUMPRODUCT((1.1/(1+$M2))^{1,2,3,4,5})+$K2*1.610510*1.0600/($M2-0.0600)/(1+$M2)^5 | E5: =$K2*SUMPRODUCT((1.1/(1+$M2))^{1,2,3,4,5})+$K2*1.610510*1.0700/($M2-0.0700)/(1+$M2)^5
A6: 0.12 | B6: =$K2*SUMPRODUCT((1.12/(1+$M2))^{1,2,3,4,5})+$K2*1.762342*1.0400/($M2-0.0400)/(1+$M2)^5 | C6: =$K2*SUMPRODUCT((1.12/(1+$M2))^{1,2,3,4,5})+$K2*1.762342*1.0500/($M2-0.0500)/(1+$M2)^5 | D6: =$K2*SUMPRODUCT((1.12/(1+$M2))^{1,2,3,4,5})+$K2*1.762342*1.0600/($M2-0.0600)/(1+$M2)^5 | E6: =$K2*SUMPRODUCT((1.12/(1+$M2))^{1,2,3,4,5})+$K2*1.762342*1.0700/($M2-0.0700)/(1+$M2)^5
A7: 0.14 | B7: =$K2*SUMPRODUCT((1.1400000000000001/(1+$M2))^{1,2,3,4,5})+$K2*1.925415*1.0400/($M2-0.0400)/(1+$M2)^5 | C7: =$K2*SUMPRODUCT((1.1400000000000001/(1+$M2))^{1,2,3,4,5})+$K2*1.925415*1.0500/($M2-0.0500)/(1+$M2)^5 | D7: =$K2*SUMPRODUCT((1.1400000000000001/(1+$M2))^{1,2,3,4,5})+$K2*1.925415*1.0600/($M2-0.0600)/(1+$M2)^5 | E7: =$K2*SUMPRODUCT((1.1400000000000001/(1+$M2))^{1,2,3,4,5})+$K2*1.925415*1.0700/($M2-0.0700)/(1+$M2)^5
A8: 0.15 | B8: =$K2*SUMPRODUCT((1.15/(1+$M2))^{1,2,3,4,5})+$K2*2.011357*1.0400/($M2-0.0400)/(1+$M2)^5 | C8: =$K2*SUMPRODUCT((1.15/(1+$M2))^{1,2,3,4,5})+$K2*2.011357*1.0500/($M2-0.0500)/(1+$M2)^5 | D8: =$K2*SUMPRODUCT((1.15/(1+$M2))^{1,2,3,4,5})+$K2*2.011357*1.0600/($M2-0.0600)/(1+$M2)^5 | E8: =$K2*SUMPRODUCT((1.15/(1+$M2))^{1,2,3,4,5})+$K2*2.011357*1.0700/($M2-0.0700)/(1+$M2)^5
A9: 0.16 | B9: =$K2*SUMPRODUCT((1.16/(1+$M2))^{1,2,3,4,5})+$K2*2.100342*1.0400/($M2-0.0400)/(1+$M2)^5 | C9: =$K2*SUMPRODUCT((1.16/(1+$M2))^{1,2,3,4,5})+$K2*2.100342*1.0500/($M2-0.0500)/(1+$M2)^5 | D9: =$K2*SUMPRODUCT((1.16/(1+$M2))^{1,2,3,4,5})+$K2*2.100342*1.0600/($M2-0.0600)/(1+$M2)^5 | E9: =$K2*SUMPRODUCT((1.16/(1+$M2))^{1,2,3,4,5})+$K2*2.100342*1.0700/($M2-0.0700)/(1+$M2)^5
A10: 0.17 | B10: =$K2*SUMPRODUCT((1.17/(1+$M2))^{1,2,3,4,5})+$K2*2.192448*1.0400/($M2-0.0400)/(1+$M2)^5 | C10: =$K2*SUMPRODUCT((1.17/(1+$M2))^{1,2,3,4,5})+$K2*2.192448*1.0500/($M2-0.0500)/(1+$M2)^5 | D10: =$K2*SUMPRODUCT((1.17/(1+$M2))^{1,2,3,4,5})+$K2*2.192448*1.0600/($M2-0.0600)/(1+$M2)^5 | E10: =$K2*SUMPRODUCT((1.17/(1+$M2))^{1,2,3,4,5})+$K2*2.192448*1.0700/($M2-0.0700)/(1+$M2)^5
A11: 0.18 | B11: =$K2*SUMPRODUCT((1.18/(1+$M2))^{1,2,3,4,5})+$K2*2.287758*1.0400/($M2-0.0400)/(1+$M2)^5 | C11: =$K2*SUMPRODUCT((1.18/(1+$M2))^{1,2,3,4,5})+$K2*2.287758*1.0500/($M2-0.0500)/(1+$M2)^5 | D11: =$K2*SUMPRODUCT((1.18/(1+$M2))^{1,2,3,4,5})+$K2*2.287758*1.0600/($M2-0.0600)/(1+$M2)^5 | E11: =$K2*SUMPRODUCT((1.18/(1+$M2))^{1,2,3,4,5})+$K2*2.287758*1.0700/($M2-0.0700)/(1+$M2)^5
A12: 0.19 | B12: =$K2*SUMPRODUCT((1.19/(1+$M2))^{1,2,3,4,5})+$K2*2.386354*1.0400/($M2-0.0400)/(1+$M2)^5 | C12: =$K2*SUMPRODUCT((1.19/(1+$M2))^{1,2,3,4,5})+$K2*2.386354*1.0500/($M2-0.0500)/(1+$M2)^5 | D12: =$K2*SUMPRODUCT((1.19/(1+$M2))^{1,2,3,4,5})+$K2*2.386354*1.0600/($M2-0.0600)/(1+$M2)^5 | E12: =$K2*SUMPRODUCT((1.19/(1+$M2))^{1,2,3,4,5})+$K2*2.386354*1.0700/($M2-0.0700)/(1+$M2)^5
A13: 0.2 | B13: =$K2*SUMPRODUCT((1.2/(1+$M2))^{1,2,3,4,5})+$K2*2.488320*1.0400/($M2-0.0400)/(1+$M2)^5 | C13: =$K2*SUMPRODUCT((1.2/(1+$M2))^{1,2,3,4,5})+$K2*2.488320*1.0500/($M2-0.0500)/(1+$M2)^5 | D13: =$K2*SUMPRODUCT((1.2/(1+$M2))^{1,2,3,4,5})+$K2*2.488320*1.0600/($M2-0.0600)/(1+$M2)^5 | E13: =$K2*SUMPRODUCT((1.2/(1+$M2))^{1,2,3,4,5})+$K2*2.488320*1.0700/($M2-0.0700)/(1+$M2)^5
A14: 0.22 | B14: =$K2*SUMPRODUCT((1.22/(1+$M2))^{1,2,3,4,5})+$K2*2.702708*1.0400/($M2-0.0400)/(1+$M2)^5 | C14: =$K2*SUMPRODUCT((1.22/(1+$M2))^{1,2,3,4,5})+$K2*2.702708*1.0500/($M2-0.0500)/(1+$M2)^5 | D14: =$K2*SUMPRODUCT((1.22/(1+$M2))^{1,2,3,4,5})+$K2*2.702708*1.0600/($M2-0.0600)/(1+$M2)^5 | E14: =$K2*SUMPRODUCT((1.22/(1+$M2))^{1,2,3,4,5})+$K2*2.702708*1.0700/($M2-0.0700)/(1+$M2)^5
A18: TABLE B – Intrinsic Value varying High-Growth Rate (g₁) and Cost of Equity (ke) | g₂ fixed at 6%
A19: g₁ \ ke | B19: 0.09 | C19: 0.1 | D19: 0.11 | E19: 0.1184 | F19: 0.12 | G19: 0.13 | H19: 0.14
A20: 0.1 | B20: =$K2*SUMPRODUCT((1.1000/1.0900)^{1,2,3,4,5})+$K2*1.610510*1.0600/(0.0900-0.0600)/(1+0.0900)^5 | C20: =$K2*SUMPRODUCT((1.1000/1.1000)^{1,2,3,4,5})+$K2*1.610510*1.0600/(0.1000-0.0600)/(1+0.1000)^5 | D20: =$K2*SUMPRODUCT((1.1000/1.1100)^{1,2,3,4,5})+$K2*1.610510*1.0600/(0.1100-0.0600)/(1+0.1100)^5 | E20: =$K2*SUMPRODUCT((1.1000/1.1184)^{1,2,3,4,5})+$K2*1.610510*1.0600/(0.1184-0.0600)/(1+0.1184)^5 | F20: =$K2*SUMPRODUCT((1.1000/1.1200)^{1,2,3,4,5})+$K2*1.610510*1.0600/(0.1200-0.0600)/(1+0.1200)^5 | G20: =$K2*SUMPRODUCT((1.1000/1.1300)^{1,2,3,4,5})+$K2*1.610510*1.0600/(0.1300-0.0600)/(1+0.1300)^5 | H20: =$K2*SUMPRODUCT((1.1000/1.1400)^{1,2,3,4,5})+$K2*1.610510*1.0600/(0.1400-0.0600)/(1+0.1400)^5
A21: 0.12 | B21: =$K2*SUMPRODUCT((1.1200/1.0900)^{1,2,3,4,5})+$K2*1.762342*1.0600/(0.0900-0.0600)/(1+0.0900)^5 | C21: =$K2*SUMPRODUCT((1.1200/1.1000)^{1,2,3,4,5})+$K2*1.762342*1.0600/(0.1000-0.0600)/(1+0.1000)^5 | D21: =$K2*SUMPRODUCT((1.1200/1.1100)^{1,2,3,4,5})+$K2*1.762342*1.0600/(0.1100-0.0600)/(1+0.1100)^5 | E21: =$K2*SUMPRODUCT((1.1200/1.1184)^{1,2,3,4,5})+$K2*1.762342*1.0600/(0.1184-0.0600)/(1+0.1184)^5 | F21: =$K2*SUMPRODUCT((1.1200/1.1200)^{1,2,3,4,5})+$K2*1.762342*1.0600/(0.1200-0.0600)/(1+0.1200)^5 | G21: =$K2*SUMPRODUCT((1.1200/1.1300)^{1,2,3,4,5})+$K2*1.762342*1.0600/(0.1300-0.0600)/(1+0.1300)^5 | H21: =$K2*SUMPRODUCT((1.1200/1.1400)^{1,2,3,4,5})+$K2*1.762342*1.0600/(0.1400-0.0600)/(1+0.1400)^5
A22: 0.14 | B22: =$K2*SUMPRODUCT((1.1400/1.0900)^{1,2,3,4,5})+$K2*1.925415*1.0600/(0.0900-0.0600)/(1+0.0900)^5 | C22: =$K2*SUMPRODUCT((1.1400/1.1000)^{1,2,3,4,5})+$K2*1.925415*1.0600/(0.1000-0.0600)/(1+0.1000)^5 | D22: =$K2*SUMPRODUCT((1.1400/1.1100)^{1,2,3,4,5})+$K2*1.925415*1.0600/(0.1100-0.0600)/(1+0.1100)^5 | E22: =$K2*SUMPRODUCT((1.1400/1.1184)^{1,2,3,4,5})+$K2*1.925415*1.0600/(0.1184-0.0600)/(1+0.1184)^5 | F22: =$K2*SUMPRODUCT((1.1400/1.1200)^{1,2,3,4,5})+$K2*1.925415*1.0600/(0.1200-0.0600)/(1+0.1200)^5 | G22: =$K2*SUMPRODUCT((1.1400/1.1300)^{1,2,3,4,5})+$K2*1.925415*1.0600/(0.1300-0.0600)/(1+0.1300)^5 | H22: =$K2*SUMPRODUCT((1.1400/1.1400)^{1,2,3,4,5})+$K2*1.925415*1.0600/(0.1400-0.0600)/(1+0.1400)^5
A23: 0.15 | B23: =$K2*SUMPRODUCT((1.1500/1.0900)^{1,2,3,4,5})+$K2*2.011357*1.0600/(0.0900-0.0600)/(1+0.0900)^5 | C23: =$K2*SUMPRODUCT((1.1500/1.1000)^{1,2,3,4,5})+$K2*2.011357*1.0600/(0.1000-0.0600)/(1+0.1000)^5 | D23: =$K2*SUMPRODUCT((1.1500/1.1100)^{1,2,3,4,5})+$K2*2.011357*1.0600/(0.1100-0.0600)/(1+0.1100)^5 | E23: =$K2*SUMPRODUCT((1.1500/1.1184)^{1,2,3,4,5})+$K2*2.011357*1.0600/(0.1184-0.0600)/(1+0.1184)^5 | F23: =$K2*SUMPRODUCT((1.1500/1.1200)^{1,2,3,4,5})+$K2*2.011357*1.0600/(0.1200-0.0600)/(1+0.1200)^5 | G23: =$K2*SUMPRODUCT((1.1500/1.1300)^{1,2,3,4,5})+$K2*2.011357*1.0600/(0.1300-0.0600)/(1+0.1300)^5 | H23: =$K2*SUMPRODUCT((1.1500/1.1400)^{1,2,3,4,5})+$K2*2.011357*1.0600/(0.1400-0.0600)/(1+0.1400)^5
A24: 0.16 | B24: =$K2*SUMPRODUCT((1.1600/1.0900)^{1,2,3,4,5})+$K2*2.100342*1.0600/(0.0900-0.0600)/(1+0.0900)^5 | C24: =$K2*SUMPRODUCT((1.1600/1.1000)^{1,2,3,4,5})+$K2*2.100342*1.0600/(0.1000-0.0600)/(1+0.1000)^5 | D24: =$K2*SUMPRODUCT((1.1600/1.1100)^{1,2,3,4,5})+$K2*2.100342*1.0600/(0.1100-0.0600)/(1+0.1100)^5 | E24: =$K2*SUMPRODUCT((1.1600/1.1184)^{1,2,3,4,5})+$K2*2.100342*1.0600/(0.1184-0.0600)/(1+0.1184)^5 | F24: =$K2*SUMPRODUCT((1.1600/1.1200)^{1,2,3,4,5})+$K2*2.100342*1.0600/(0.1200-0.0600)/(1+0.1200)^5 | G24: =$K2*SUMPRODUCT((1.1600/1.1300)^{1,2,3,4,5})+$K2*2.100342*1.0600/(0.1300-0.0600)/(1+0.1300)^5 | H24: =$K2*SUMPRODUCT((1.1600/1.1400)^{1,2,3,4,5})+$K2*2.100342*1.0600/(0.1400-0.0600)/(1+0.1400)^5
A25: 0.17 | B25: =$K2*SUMPRODUCT((1.1700/1.0900)^{1,2,3,4,5})+$K2*2.192448*1.0600/(0.0900-0.0600)/(1+0.0900)^5 | C25: =$K2*SUMPRODUCT((1.1700/1.1000)^{1,2,3,4,5})+$K2*2.192448*1.0600/(0.1000-0.0600)/(1+0.1000)^5 | D25: =$K2*SUMPRODUCT((1.1700/1.1100)^{1,2,3,4,5})+$K2*2.192448*1.0600/(0.1100-0.0600)/(1+0.1100)^5 | E25: =$K2*SUMPRODUCT((1.1700/1.1184)^{1,2,3,4,5})+$K2*2.192448*1.0600/(0.1184-0.0600)/(1+0.1184)^5 | F25: =$K2*SUMPRODUCT((1.1700/1.1200)^{1,2,3,4,5})+$K2*2.192448*1.0600/(0.1200-0.0600)/(1+0.1200)^5 | G25: =$K2*SUMPRODUCT((1.1700/1.1300)^{1,2,3,4,5})+$K2*2.192448*1.0600/(0.1300-0.0600)/(1+0.1300)^5 | H25: =$K2*SUMPRODUCT((1.1700/1.1400)^{1,2,3,4,5})+$K2*2.192448*1.0600/(0.1400-0.0600)/(1+0.1400)^5
A26: 0.18 | B26: =$K2*SUMPRODUCT((1.1800/1.0900)^{1,2,3,4,5})+$K2*2.287758*1.0600/(0.0900-0.0600)/(1+0.0900)^5 | C26: =$K2*SUMPRODUCT((1.1800/1.1000)^{1,2,3,4,5})+$K2*2.287758*1.0600/(0.1000-0.0600)/(1+0.1000)^5 | D26: =$K2*SUMPRODUCT((1.1800/1.1100)^{1,2,3,4,5})+$K2*2.287758*1.0600/(0.1100-0.0600)/(1+0.1100)^5 | E26: =$K2*SUMPRODUCT((1.1800/1.1184)^{1,2,3,4,5})+$K2*2.287758*1.0600/(0.1184-0.0600)/(1+0.1184)^5 | F26: =$K2*SUMPRODUCT((1.1800/1.1200)^{1,2,3,4,5})+$K2*2.287758*1.0600/(0.1200-0.0600)/(1+0.1200)^5 | G26: =$K2*SUMPRODUCT((1.1800/1.1300)^{1,2,3,4,5})+$K2*2.287758*1.0600/(0.1300-0.0600)/(1+0.1300)^5 | H26: =$K2*SUMPRODUCT((1.1800/1.1400)^{1,2,3,4,5})+$K2*2.287758*1.0600/(0.1400-0.0600)/(1+0.1400)^5
A27: 0.19 | B27: =$K2*SUMPRODUCT((1.1900/1.0900)^{1,2,3,4,5})+$K2*2.386354*1.0600/(0.0900-0.0600)/(1+0.0900)^5 | C27: =$K2*SUMPRODUCT((1.1900/1.1000)^{1,2,3,4,5})+$K2*2.386354*1.0600/(0.1000-0.0600)/(1+0.1000)^5 | D27: =$K2*SUMPRODUCT((1.1900/1.1100)^{1,2,3,4,5})+$K2*2.386354*1.0600/(0.1100-0.0600)/(1+0.1100)^5 | E27: =$K2*SUMPRODUCT((1.1900/1.1184)^{1,2,3,4,5})+$K2*2.386354*1.0600/(0.1184-0.0600)/(1+0.1184)^5 | F27: =$K2*SUMPRODUCT((1.1900/1.1200)^{1,2,3,4,5})+$K2*2.386354*1.0600/(0.1200-0.0600)/(1+0.1200)^5 | G27: =$K2*SUMPRODUCT((1.1900/1.1300)^{1,2,3,4,5})+$K2*2.386354*1.0600/(0.1300-0.0600)/(1+0.1300)^5 | H27: =$K2*SUMPRODUCT((1.1900/1.1400)^{1,2,3,4,5})+$K2*2.386354*1.0600/(0.1400-0.0600)/(1+0.1400)^5
A28: 0.2 | B28: =$K2*SUMPRODUCT((1.2000/1.0900)^{1,2,3,4,5})+$K2*2.488320*1.0600/(0.0900-0.0600)/(1+0.0900)^5 | C28: =$K2*SUMPRODUCT((1.2000/1.1000)^{1,2,3,4,5})+$K2*2.488320*1.0600/(0.1000-0.0600)/(1+0.1000)^5 | D28: =$K2*SUMPRODUCT((1.2000/1.1100)^{1,2,3,4,5})+$K2*2.488320*1.0600/(0.1100-0.0600)/(1+0.1100)^5 | E28: =$K2*SUMPRODUCT((1.2000/1.1184)^{1,2,3,4,5})+$K2*2.488320*1.0600/(0.1184-0.0600)/(1+0.1184)^5 | F28: =$K2*SUMPRODUCT((1.2000/1.1200)^{1,2,3,4,5})+$K2*2.488320*1.0600/(0.1200-0.0600)/(1+0.1200)^5 | G28: =$K2*SUMPRODUCT((1.2000/1.1300)^{1,2,3,4,5})+$K2*2.488320*1.0600/(0.1300-0.0600)/(1+0.1300)^5 | H28: =$K2*SUMPRODUCT((1.2000/1.1400)^{1,2,3,4,5})+$K2*2.488320*1.0600/(0.1400-0.0600)/(1+0.1400)^5
A29: 0.22 | B29: =$K2*SUMPRODUCT((1.2200/1.0900)^{1,2,3,4,5})+$K2*2.702708*1.0600/(0.0900-0.0600)/(1+0.0900)^5 | C29: =$K2*SUMPRODUCT((1.2200/1.1000)^{1,2,3,4,5})+$K2*2.702708*1.0600/(0.1000-0.0600)/(1+0.1000)^5 | D29: =$K2*SUMPRODUCT((1.2200/1.1100)^{1,2,3,4,5})+$K2*2.702708*1.0600/(0.1100-0.0600)/(1+0.1100)^5 | E29: =$K2*SUMPRODUCT((1.2200/1.1184)^{1,2,3,4,5})+$K2*2.702708*1.0600/(0.1184-0.0600)/(1+0.1184)^5 | F29: =$K2*SUMPRODUCT((1.2200/1.1200)^{1,2,3,4,5})+$K2*2.702708*1.0600/(0.1200-0.0600)/(1+0.1200)^5 | G29: =$K2*SUMPRODUCT((1.2200/1.1300)^{1,2,3,4,5})+$K2*2.702708*1.0600/(0.1300-0.0600)/(1+0.1300)^5 | H29: =$K2*SUMPRODUCT((1.2200/1.1400)^{1,2,3,4,5})+$K2*2.702708*1.0600/(0.1400-0.0600)/(1+0.1400)^5
A32: Current Market Price (CMP): ₹3,200 | GOLD = Adopted assumptions → Base Case Intrinsic Value | Any cell ≥ ₹3,200 implies undervaluation
A34: g₁ | B34: IV (ke=11.84%, g₂=6%) | C34: CMP = ₹3,200
A35: 0.1 | B35: =$K2*SUMPRODUCT((1.1000/1.1184)^{1,2,3,4,5})+$K2*1.610510*1.0600/(0.1184-0.0600)/(1+0.1184)^5 | C35: 3200
A36: 0.12 | B36: =$K2*SUMPRODUCT((1.1200/1.1184)^{1,2,3,4,5})+$K2*1.762342*1.0600/(0.1184-0.0600)/(1+0.1184)^5 | C36: 3200
A37: 0.13 | B37: =$K2*SUMPRODUCT((1.1300/1.1184)^{1,2,3,4,5})+$K2*1.842435*1.0600/(0.1184-0.0600)/(1+0.1184)^5 | C37: 3200
A38: 0.14 | B38: =$K2*SUMPRODUCT((1.1400/1.1184)^{1,2,3,4,5})+$K2*1.925415*1.0600/(0.1184-0.0600)/(1+0.1184)^5 | C38: 3200
A39: 0.15 | B39: =$K2*SUMPRODUCT((1.1500/1.1184)^{1,2,3,4,5})+$K2*2.011357*1.0600/(0.1184-0.0600)/(1+0.1184)^5 | C39: 3200
A40: 0.16 | B40: =$K2*SUMPRODUCT((1.1600/1.1184)^{1,2,3,4,5})+$K2*2.100342*1.0600/(0.1184-0.0600)/(1+0.1184)^5 | C40: 3200
A41: 0.17 | B41: =$K2*SUMPRODUCT((1.1700/1.1184)^{1,2,3,4,5})+$K2*2.192448*1.0600/(0.1184-0.0600)/(1+0.1184)^5 | C41: 3200
A42: 0.18 | B42: =$K2*SUMPRODUCT((1.1800/1.1184)^{1,2,3,4,5})+$K2*2.287758*1.0600/(0.1184-0.0600)/(1+0.1184)^5 | C42: 3200
A43: 0.19 | B43: =$K2*SUMPRODUCT((1.1900/1.1184)^{1,2,3,4,5})+$K2*2.386354*1.0600/(0.1184-0.0600)/(1+0.1184)^5 | C43: 3200
A44: 0.2 | B44: =$K2*SUMPRODUCT((1.2000/1.1184)^{1,2,3,4,5})+$K2*2.488320*1.0600/(0.1184-0.0600)/(1+0.1184)^5 | C44: 3200
A45: 0.22 | B45: =$K2*SUMPRODUCT((1.2200/1.1184)^{1,2,3,4,5})+$K2*2.702708*1.0600/(0.1184-0.0600)/(1+0.1184)^5 | C45: 3200

Sheet Investment_Assessment
A1: INVESTMENT ASSESSMENT & CRITICAL REFLECTION – TITAN COMPANY LTD
A3: VALUATION COMPARISON DASHBOARD
A4: Intrinsic Value (FCFE Model, Base Case) | E4: =FCFE_Valuation!D48
A5: Intrinsic Value – Bull Case (g₁=20%, g₂=7%) | E5: =FCFE_Valuation!E23*1.200000/1.118400+FCFE_Valuation!E23*1.440000/1.250819+FCFE_Valuation!E23*1.728000/1.398915+FCFE_Valuation!E23*2.073600/1.564547+FCFE_Valuation!E23*2.488320/1.749789+FCFE_Valuation!E23*2.488320*1.0700/(0.1184-0.0700)/1.749789
A6: Intrinsic Value – Bear Case (g₁=12%, g₂=5%) | E6: =FCFE_Valuation!E23*1.120000/1.118400+FCFE_Valuation!E23*1.254400/1.250819+FCFE_Valuation!E23*1.404928/1.398915+FCFE_Valuation!E23*1.573519/1.564547+FCFE_Valuation!E23*1.762342/1.749789+FCFE_Valuation!E23*1.762342*1.0500/(0.1184-0.0500)/1.749789
A7: Current Market Price (CMP) | E7: =FCFE_Valuation!D49
A8: Implied P/E (Base Case) | E8: =FCFE_Valuation!D48/Financial_Data!G4
A9: Actual P/E | E9: =FCFE_Valuation!D49/Financial_Data!G4
A10: Premium over Intrinsic Value | E10: =(FCFE_Valuation!D49-FCFE_Valuation!D48)/FCFE_Valuation!D48
A11: Assessment | E11: OVERVALUED by Model
A14: INVESTMENT VERDICT
A15: Based on the two-stage FCFE model, Titan's intrinsic value is approximately ₹479 per share (Base Case), ₹723 per share (Bull Case), and ₹268 per share (Bear Case). The current market price of ₹3,200 implies a significant premium of ~568% over the base-case intrinsic value. The stock appears OVERVALUED by the FCFE model. HOWEVER, this does not necessarily imply a 'SELL' signal. The premium reflects the market's willingness to pay for Titan's intangible assets — primarily the TANISHQ brand equity, CaratLane digital platform, distribution moat, and management quality. These are not captured by FCFE. A more holistic view: the Earnings Multiplier (P/E) of Titan (~81×) versus the Indian consumer discretionary sector median (~35-40×) suggests the market is pricing in continued above-average growth. If Titan sustains 17-20% EPS CAGR for the next decade (as suggested by its historical track record), the market price may be justified on a longer-horizon discounted earnings basis. RECOMMENDATION: HOLD / ACCUMULATE on dips for long-term investors; the FCFE model undervalues brand-heavy consumer companies.
A24: CRITICAL LIMITATIONS OF THE FCFE MODEL & ASSUMPTIONS
A25: 1. Brand & Intangible Value Ignored | C25: FCFE only captures cash flow from tangible operations. Titan's Tanishq brand, loyal customer base, and jewelry craftsmanship are not reflected.
A26: 2. Static Reinvestment Rate | C26: We assume a constant reinvestment rate. In reality, Titan's capex requirements and working capital intensity vary year to year, especially with gold price fluctuations.
A27: 3. Two-Stage Simplification | C27: Growth rarely transitions cleanly from high to stable. A three-stage model (high → transition → stable) would be more realistic but requires additional assumptions.
A28: 4. Beta Instability | C28: Beta estimated from 36 monthly observations may not be stable. Different sample periods yield different betas. Sensitivity of ke to beta should be tested.
A29: 5. Growth Rate Uncertainty | C29: 17% g₁ is optimistic and depends heavily on jewelry market expansion and macroeconomic conditions. Any slowdown in India's GDP or gold demand would compress growth significantly.
A30: 6. Risk-Free Rate Changes | C30: The 91-Day T-Bill rate fluctuates with RBI monetary policy. A 100 bps increase in Rf directly raises ke and decreases intrinsic value.
A31: 7. Terminal Value Dominance | C31: ~81% of intrinsic value comes from the terminal value (PV of TV), making the model extremely sensitive to the terminal growth rate assumption.
A32: 8. Circular Logic in Debt Ratio | C32: Assuming a constant debt ratio ignores Titan's strategy of financing jewelry inventory working capital partly through consignment (gold on loan), which complicates the FCFE formula.
