Workbook

Sheet 1_Overview
A1: 🏢 TITAN COMPANY LIMITED – INTRINSIC VALUE ESTIMATION
A2: NSE: TITAN | BSE: 500114 | Sector: Consumer Discretionary – Jewellery / Watches / Eyewear
B4: COMPANY PROFILE
B5: Company Name | C5: Titan Company Limited
B6: NSE Symbol | C6: TITAN
B7: BSE Code | C7: 500114
B8: Sector | C8: Consumer Discretionary
B9: Industry | C9: Jewellery / Watches / Eyewear
B10: Market Cap (₹ Cr) | C10: ~2,90,000
B11: Face Value (₹) | C11: 1
B12: 52-Week High (₹) | C12: 3,888
B13: 52-Week Low (₹) | C13: 2,781
B14: Current Market Price (₹) | C14: =D20
B16: KEY ASSUMPTIONS & MODEL INPUTS (yellow cells = editable)
B17: Parameter | C17: Symbol | D17: Value (Edit) | E17: Unit / Source
B18: Current Market Price (₹) | C18: CMP | D18: 3450 | E18: ₹/share – NSE Apr 2025
B19: 91-Day T-Bill Rate (Rf) | C19: Rf | D19: 0.0684 | E19: Decimal – RBI Apr 2025
B20: Market Risk Premium | C20: MRP | D20: 0.065 | E20: Historical Nifty 50 excess return
B21: Beta (OLS – Sheet 2) | C21: β | D21: ='2_CAPM & Beta'!C44 | E21: See Sheet 2 – Blume adjusted
B22: Cost of Equity (CAPM) | C22: Ke | D22: =D19+(D21*D20) | E22: Ke = Rf + β × MRP
B23: High-Growth Rate (g1) | C23: g₁ | D23: ='3_Growth Rate'!C42 | E23: Justified in Sheet 3
B24: Terminal Growth Rate (g) | C24: g | D24: ='3_Growth Rate'!C44 | E24: India long-run nominal GDP ~7%
B25: High-Growth Period | C25: n | D25: 5 | E25: Years
B26: EPS FY2024 (₹) | C26: EPS₀ | D26: 72.1 | E26: Titan Annual Report FY2024
B27: DPS FY2024 (₹) | C27: DPS₀ | D27: 10 | E27: Titan Annual Report FY2024
B28: Payout Ratio | C28: PR | D28: =D28/D27 | E28: DPS₀/EPS₀
B29: Retention Ratio | C29: b | D29: =1-D29 | E29: 1 − PR
B30: ROE (FY2024) | C30: ROE | D30: 0.268 | E30: PAT/Avg Equity – Annual Report
B31: FCFE₀ per Share (₹) | C31: FCFE₀ | D31: 38.5 | E31: Computed in Sheet 4
B32: Shares Outstanding (Cr) | C32: N | D32: 88.84 | E32: BSE filings
B33: Net Income FY2024 (₹ Cr) | C33: NI | D33: 3496 | E33: P&L Statement
B34: Capex FY2024 (₹ Cr) | C34: Capex | D34: 820 | E34: Cash Flow Statement
B35: Depreciation FY2024 (₹ Cr) | C35: Dep | D35: 385 | E35: Cash Flow Statement
B36: ΔWorking Capital (₹ Cr) | C36: ΔWC | D36: 1240 | E36: Cash Flow Statement
B37: Net Borrowings (₹ Cr) | C37: ΔD | D37: 180 | E37: Balance Sheet
B38: Debt-to-Equity Ratio | C38: D/E | D38: 0.12 | E38: Balance Sheet
B41: VALUATION MODEL JUSTIFICATION
B42: Factor | C42: Explanation
B43: Chosen Model | C43: FCFE (Free Cash Flow to Equity) – Two-Stage DCF
B44: Why FCFE over DDM? | C44: Titan's dividend payout is ~14%. DDM drastically undervalues the firm. FCFE captures all cash available to equity holders, not just dividends paid.
...

Sheet 2_CAPM & Beta
A1: CAPM BETA ESTIMATION – OLS Regression of Daily Returns (TITAN vs Nifty 50)
B2: 📌 INSTRUCTIONS: Paste 3+ years (756+ trading days) of daily TITAN and Nifty 50 closing prices into the 'Raw_Data' sheet (columns B & C). Daily returns are computed as (Pt/Pt-1)−1. All regression statistics below use SLOPE, INTERCEPT, CORREL, RSQ functions and auto-update when Raw_Data is populated.
B6: OLS REGRESSION – THEORETICAL FRAMEWORK
B7: Concept | C7: Formula / Explanation
B8: Regression Model | C8: Ri,t = α + β·Rm,t + εt
B9: Variables | C9: Ri,t = TITAN daily return, Rm,t = Nifty 50 daily return, εt = i.i.d. error
B10: Beta Formula | C10: β = Cov(Ri, Rm) / Var(Rm) = SLOPE(Ti_returns, Ni_returns)
B11: Alpha Formula | C11: α = Mean(Ri) − β·Mean(Rm) = INTERCEPT(...)
B12: R² Interpretation | C12: Proportion of TITAN return variance explained by market; R²=0 → no linear relationship
B13: Blume Adjustment | C13: β_adj = (2/3)·β_raw + (1/3)·1 → shrinks beta toward 1 for better forward forecasts
B15: REGRESSION DATA SUMMARY
B16: Statistic | C16: Formula | D16: Value
B17: Data Period | C17: Apr 2021 – Mar 2024 | D17: 3 years (manual entry)
B18: No. of Observations | C18: ~756 trading days | D18: Min. 3 yrs required
B19: TITAN Avg Daily Return | C19: =AVERAGE(Raw_Data!D3:D758) | D19: =AVERAGE(Raw_Data!D3:D758)
B20: Nifty 50 Avg Daily Return | C20: =AVERAGE(Raw_Data!E3:E758) | D20: =AVERAGE(Raw_Data!E3:E758)
B21: TITAN Return Std Dev | C21: =STDEV(Raw_Data!D3:D758) | D21: =STDEV(Raw_Data!D3:D758)
B22: Nifty 50 Return Std Dev | C22: =STDEV(Raw_Data!E3:E758) | D22: =STDEV(Raw_Data!E3:E758)
B23: Covariance(TITAN, Nifty) | C23: =COVARIANCE.S(Raw_Data!D3:D758,Raw_Data!E3:E758) | D23: =COVARIANCE.S(Raw_Data!D3:D758,Raw_Data!E3:E758)
B24: Variance(Nifty 50) | C24: =VAR(Raw_Data!E3:E758) | D24: =VAR(Raw_Data!E3:E758)
B25: Correlation ρ | C25: =CORREL(Raw_Data!D3:D758,Raw_Data!E3:E758) | D25: =CORREL(Raw_Data!D3:D758,Raw_Data!E3:E758)
B27: OLS REGRESSION OUTPUT
B28: Statistic | C28: Formula | D28: Value | E28: Interpretation
B29: Alpha (α – daily) | C29: =INTERCEPT(Raw_Data!D3:D758,Raw_Data!E3:E758) | D29: =INTERCEPT(Raw_Data!D3:D758,Raw_Data!E3:E758) | E29: Daily Jensen's alpha; ~0 expected
B30: Beta (β – Raw) | C30: =SLOPE(Raw_Data!D3:D758,Raw_Data!E3:E758) | D30: =SLOPE(Raw_Data!D3:D758,Raw_Data!E3:E758) | E30: Systematic risk vs. Nifty 50
B31: R-Squared (R²) | C31: =RSQ(Raw_Data!D3:D758,Raw_Data!E3:E758) | D31: =RSQ(Raw_Data!D3:D758,Raw_Data!E3:E758) | E31: % of variance explained by market
B32: t-stat (β) | C32: =D30/STDEV(Raw_Data!D3:D758)*SQRT(756) | D32: =D30/STDEV(Raw_Data!D3:D758)*SQRT(756) | E32: >1.96 = sig. at 5%
B33: 95% CI – Beta Low | C33: =D30-1.96*STDEV(Raw_Data!D3:D758)/SQRT(756) | D33: =D30-1.96*STDEV(Raw_Data!D3:D758)/SQRT(756) | E33: Lower bound
B34: 95% CI – Beta High | C34: =D30+1.96*STDEV(Raw_Data!D3:D758)/SQRT(756) | D34: =D30+1.96*STDEV(Raw_Data!D3:D758)/SQRT(756) | E34: Upper bound
B35: Adjusted Beta (Blume) | C35: =(2/3)*D30+(1/3)*1 | D35: =(2/3)*D30+(1/3)*1 | E35: Regresses toward 1 over time
B37: CAPM – COST OF EQUITY CALCULATION
B38: Input | C38: Value | D38: Format
B39: Risk-Free Rate (Rf) | C39: ='1_Overview'!D19 | D39: 0.00%
B40: Market Risk Premium (MRP) | C40: ='1_Overview'!D20 | D40: 0.00%
B41: Beta (Adjusted – Blume) | C41: =D35 | D41: 0.000
B43: COST OF EQUITY Ke = Rf + β × MRP | C43: =D39+D41*D40
C44: =D35 | D44: Adjusted Beta (referenced by Sheet 1)
B46: SAMPLE DAILY RETURN ROWS (illustrative – paste full 756+ rows into Raw_Data sheet)
B47: Date | C47: TITAN Close (₹) | D47: Nifty 50 Close | E47: TITAN Return | F47: Nifty 50 Return
B48: 01-Apr-2021 | C48: 2618.45 | D48: 14690.7
...

Sheet 3_Growth Rate
A1: TITAN COMPANY – GROWTH RATE ESTIMATION (Three Approaches)
B3: APPROACH 1: HISTORICAL EPS GROWTH (CAGR)
B4: Fiscal Year | C4: Reported EPS (₹) | D4: YoY Growth (%) | E4: Notes
B5: FY2019 | C5: 14.3 | E5: Base Year
B6: FY2020 | C6: 12.9 | D6: =(C6-C5)/C5 | E6: COVID early impact
B7: FY2021 | C7: 8.5 | D7: =(C7-C6)/C6 | E7: Pandemic low
B8: FY2022 | C8: 27.6 | D8: =(C8-C7)/C7 | E8: Sharp recovery
B9: FY2023 | C9: 53.8 | D9: =(C9-C8)/C8 | E9: Strong growth
B10: FY2024 | C10: 72.1 | D10: =(C10-C9)/C9 | E10: Latest reported
B12: 5-Year EPS CAGR (FY2019→FY2024) | C12: =(C10/C5)^(1/5)-1 | D12: FY19→FY24 CAGR
B13: Note: FY2021 distorted by COVID → 3-yr CAGR preferred
B14: 3-Year EPS CAGR (FY2022→FY2024) | C14: =(C10/C8)^(1/2)-1 | D14: Excludes COVID distortion
B16: APPROACH 2: SUSTAINABLE GROWTH RATE (SGR = ROE × b)
B17: Parameter | C17: Symbol | D17: Value | E17: Source
B18: Return on Equity (ROE – FY2024) | C18: ROE | D18: ='1_Overview'!D31 | E18: PAT / Avg Equity
B19: EPS FY2024 (₹) | C19: EPS₀ | D19: ='1_Overview'!D27 | E19: Annual Report
B20: DPS FY2024 (₹) | C20: DPS₀ | D20: ='1_Overview'!D28 | E20: Annual Report
B21: Payout Ratio (PR = DPS/EPS) | C21: PR | D21: ='1_Overview'!D29 | E21: =DPS₀/EPS₀
B22: Retention Ratio (b = 1−PR) | C22: b | D22: ='1_Overview'!D30 | E22: =1−PR
B23: SGR = ROE × b | C23: SGR | D23: =C18*C22 | E23: Fundable internal growth ceiling
B25: APPROACH 3: ANALYST CONSENSUS FORECAST
B26: Broker / Source | C26: FY2025E EPS (₹) | D26: FY2026E EPS (₹) | E26: Implied 2-yr CAGR | F26: Rating
B27: Motilal Oswal | C27: 82.5 | D27: 97 | E27: =(D27/C10)^(1/2)-1 | F27: BUY
B28: ICICI Securities | C28: 80 | D28: 94 | E28: =(D28/C10)^(1/2)-1 | F28: BUY
B29: Kotak Securities | C29: 78.5 | D29: 91.5 | E29: =(D29/C10)^(1/2)-1 | F29: ADD
B30: Emkay Global | C30: 83 | D30: 98.5 | E30: =(D30/C10)^(1/2)-1 | F30: BUY
B31: HDFC Securities | C31: 79 | D31: 93 | E31: =(D31/C10)^(1/2)-1 | F31: BUY
B32: CONSENSUS (AVG) | C32: =AVERAGE(C27:C31) | D32: =AVERAGE(D27:D31) | E32: =AVERAGE(E27:E31)
B35: GROWTH RATE SUMMARY & ADOPTED RATE
B36: Approach | C36: Estimated g | D36: Weight | E36: Weighted g
B37: 5-Year Historical CAGR (FY19→FY24) | C37: =C12 | D37: 0.3 | E37: =C37*D37
B38: 3-Year CAGR excl. COVID (FY22→FY24) | C38: =C14 | D38: 0.2 | E38: =C38*D38
B39: SGR (ROE × b) | C39: =C23 | D39: 0.2 | E39: =C39*D39
B40: Analyst Consensus 2-yr CAGR | C40: =E32 | D40: 0.3 | E40: =C40*D40
B42: ADOPTED HIGH-GROWTH RATE (g₁) | C42: =SUM(E37:E40) | D42: Weighted average of 4 approaches
B44: TERMINAL GROWTH RATE (g) | C44: 0.07 | D44: India long-run nominal GDP growth proxy
B46: JUSTIFICATION OF ADOPTED GROWTH RATE
B47: 1. Weighted blended rate balances historical performance with forward analyst views.
B48: 2. COVID distorted FY21 EPS (₹8.50); excluding it gives a more representative 3-yr CAGR of ~62%, moderated by weighting.
B49: 3. SGR (ROE × b) provides the theoretically sustainable growth ceiling from retained earnings alone.
...

Sheet 4_FCFE Valuation
A1: TITAN COMPANY – TWO-STAGE FCFE VALUATION MODEL
B3: FCFE CALCULATION (FY2024 Base)
B4: Component | C4: Formula / Reference | D4: Value (₹ Cr) | E4: Notes
B5: Net Income (NI) | C5: ='1_Overview'!D34 | D5: ='1_Overview'!D34 | E5: P&L – FY2024
B6: Capex | C6: ='1_Overview'!D35 | D6: ='1_Overview'!D35 | E6: Cash Flow Statement
B7: Depreciation (Dep) | C7: ='1_Overview'!D36 | D7: ='1_Overview'!D36 | E7: Cash Flow Statement
B8: Net Capex = Capex − Dep | C8: =C6-C7 | D8: =C6-C7
B9: ΔWorking Capital (ΔWC) | C9: ='1_Overview'!D37 | D9: ='1_Overview'!D37
B10: Net Borrowings (ΔD) | C10: ='1_Overview'!D38 | D10: ='1_Overview'!D38
B11: Debt Ratio δ = D/(D+E) | C11: ='1_Overview'!D39/(1+'1_Overview'!D39) | D11: ='1_Overview'!D39/(1+'1_Overview'!D39) | E11: From D/E ratio
B12: FCFE (₹ Cr) = NI−Net Capex×(1−δ)−ΔWC×(1−δ) | C12: =C5-(C8*(1-C11))-(C9*(1-C11)) | D12: =C5-(C8*(1-C11))-(C9*(1-C11)) | E12: FCFE formula
B13: Shares Outstanding (Cr) | C13: ='1_Overview'!D33 | D13: ='1_Overview'!D33
B14: FCFE per Share (₹) | C14: =C12/C13 | D14: =C12/C13 | E14: Used as FCFE₀
B17: STAGE 1: HIGH-GROWTH PHASE (Years 1 to 5)
B18: High-Growth Rate (g₁) | C18: ='3_Growth Rate'!C42 | D18: Cost of Equity (Ke) | E18: ='2_CAPM & Beta'!C43 | F18: FCFE₀ (₹/sh) | G18: =C14
B19: Year | C19: FCFE (₹/sh) | D19: Discount Factor | E19: PV of FCFE (₹/sh) | F19: Cumulative PV (₹/sh)
B20: Year 1 | C20: =$G$18*(1+$C$18)^1 | D20: =1/(1+$E$18)^1 | E20: =C20*D20 | F20: =SUM(E$20:E20)
B21: Year 2 | C21: =$G$18*(1+$C$18)^2 | D21: =1/(1+$E$18)^2 | E21: =C21*D21 | F21: =SUM(E$20:E21)
B22: Year 3 | C22: =$G$18*(1+$C$18)^3 | D22: =1/(1+$E$18)^3 | E22: =C22*D22 | F22: =SUM(E$20:E22)
B23: Year 4 | C23: =$G$18*(1+$C$18)^4 | D23: =1/(1+$E$18)^4 | E23: =C23*D23 | F23: =SUM(E$20:E23)
B24: Year 5 | C24: =$G$18*(1+$C$18)^5 | D24: =1/(1+$E$18)^5 | E24: =C24*D24 | F24: =SUM(E$20:E24)
B26: SUM PV – Stage 1 | E26: =SUM(E20:E24)
B28: STAGE 2: TERMINAL VALUE (Gordon Growth Model)
B29: Component | C29: Formula | D29: Value (₹/sh) | E29: Notes
B30: Terminal Growth Rate (g) | C30: ='1_Overview'!D24 | D30: ='1_Overview'!D24 | E30: India nominal GDP growth
B31: FCFE at Year 6 (FCFE₆) | C31: =C24*(1+'1_Overview'!D24) | D31: =C24*(1+'1_Overview'!D24) | E31: FCFE₅ × (1+g)
B32: Terminal Value at Year 5 | C32: =C31/($E$18-C30) | D32: =C31/($E$18-C30) | E32: =FCFE₆ / (Ke − g) [Gordon Growth]
B33: PV of Terminal Value | C33: =C32/(1+$E$18)^5 | D33: =C32/(1+$E$18)^5 | E33: TV₅ discounted back 5 years
B34: TV as % of Total IV | C34: =C33/(C26+C33) | D34: =C33/(C26+C33) | E34: Sanity check – ideally < 80%
B35: Ke > g? (stability check) | C35: =IF(E18>C30,"✔ STABLE: Ke > g","✘ MODEL UNSTABLE") | D35: =IF(E18>C30,"✔ STABLE","✘ UNSTABLE") | E35: If Ke ≤ g, TV is undefined
B38: INTRINSIC VALUE PER SHARE – FINAL CALCULATION
B39: Component | C39: Calculation | D39: Value (₹/sh) | E39: Notes
B40: PV of Stage 1 FCFEs | C40: =E26 | D40: =E26 | E40: Sum of PVs – Years 1–5
B41: PV of Terminal Value | C41: =C33 | D41: =C33 | E41: Gordon Growth PV
B42: INTRINSIC VALUE PER SHARE (₹) | C42: =C40+C41 | D42: =C40+C41 | E42: =Stage1 + TV
B43: Current Market Price (₹) | C43: ='1_Overview'!D18 | D43: ='1_Overview'!D18 | E43: NSE CMP
B44: Upside / Downside | C44: =(C42-C43)/C43 | D44: =(C42-C43)/C43 | E44: (IV−CMP)/CMP
B45: Recommendation | C45: =IF(C43<C42*0.85,"STRONG BUY",IF(C43<C42,"BUY",IF(C43<C42*1.1,"FAIRLY VALUED","OVERVALUED"))) | D45: =IF(C43<C42*0.85,"STRONG BUY",IF(C43<C42,"BUY",IF(C43<C42*1.1,"FAIRLY VALUED","OVERVALUED"))) | E45: CMP vs IV threshold

Sheet 5_Sensitivity
A1: TITAN – SENSITIVITY ANALYSIS: Intrinsic Value per Share (₹)
B3: TABLE 1: IV (₹) | Rows = High-Growth Rate (g₁) | Columns = Cost of Equity (Ke) | Terminal g = 7%
B4: g₁ ╲ Ke → | C4: 0.1 | D4: 0.11 | E4: 0.12 | F4: 0.13 | G4: 0.14 | H4: 0.15 | I4: 0.16 | J4: 0.17 | K4: 0.18 | L4: 0.19
B5: 0.1 | C5: 1566 | D5: 1172 | E5: 935 | F5: 778 | G5: 665 | H5: 581 | I5: 516 | J5: 463 | K5: 420 | L5: 385
B6: 0.12 | C6: 1706 | D6: 1275 | E6: 1016 | F6: 844 | G6: 721 | H6: 629 | I6: 558 | J6: 500 | K6: 454 | L6: 415
B7: 0.14 | C7: 1856 | D7: 1385 | E7: 1103 | F7: 915 | G7: 781 | H7: 680 | I7: 602 | J7: 540 | K7: 489 | L7: 447
B8: 0.16 | C8: 2017 | D8: 1504 | E8: 1196 | F8: 991 | G8: 845 | H8: 735 | I8: 650 | J8: 582 | K8: 527 | L8: 481
B9: 0.18 | C9: 2189 | D9: 1630 | E9: 1295 | F9: 1072 | G9: 913 | H9: 794 | I9: 701 | J9: 627 | K9: 567 | L9: 517
B10: 0.2 | C10: 2373 | D10: 1766 | E10: 1401 | F10: 1159 | G10: 986 | H10: 856 | I10: 756 | J10: 675 | K10: 610 | L10: 555
B11: 0.22 | C11: 2570 | D11: 1910 | E11: 1514 | F11: 1251 | G11: 1063 | H11: 923 | I11: 814 | J11: 726 | K11: 655 | L11: 596
B12: 0.24 | C12: 2779 | D12: 2063 | E12: 1634 | F12: 1349 | G12: 1146 | H12: 993 | I12: 875 | J12: 781 | K12: 704 | L12: 640
B14: Green = Undervalued (IV > 1.15×CMP) | E14: Yellow = Fairly Valued (0.95–1.15×CMP) | H14: Red = Overvalued (IV < 0.95×CMP)
B16: TABLE 2: IV (₹) | Rows = g₁ | Columns = Terminal Growth (g) | Ke = 12.84% (base)
B17: g₁ ╲ g → | C17: 0.04 | D17: 0.05 | E17: 0.06 | F17: 0.065 | G17: 0.07 | H17: 0.075 | I17: 0.08 | J17: 0.085 | K17: 0.09 | L17: 0.095
B18: 0.1 | C18: 577 | D18: 632 | E18: 704 | F18: 748 | G18: 799 | H18: 861 | I18: 935 | J18: 1026 | K18: 1141 | L18: 1290
B19: 0.12 | C19: 625 | D19: 685 | E19: 763 | F19: 811 | G19: 868 | H19: 935 | I19: 1016 | J19: 1115 | K19: 1241 | L19: 1404
B20: 0.14 | C20: 675 | D20: 741 | E20: 826 | F20: 879 | G20: 941 | H20: 1014 | I20: 1103 | J20: 1212 | K20: 1349 | L20: 1527
B21: 0.16 | C21: 729 | D21: 801 | E21: 894 | F21: 952 | G21: 1019 | H21: 1099 | I21: 1196 | J21: 1314 | K21: 1464 | L21: 1658
B22: 0.18 | C22: 787 | D22: 865 | E22: 967 | F22: 1029 | G22: 1103 | H22: 1190 | I22: 1295 | J22: 1424 | K22: 1587 | L22: 1799
B23: 0.2 | C23: 848 | D23: 934 | E23: 1044 | F23: 1112 | G23: 1192 | H23: 1287 | I23: 1401 | J23: 1542 | K23: 1719 | L23: 1949
B24: 0.22 | C24: 914 | D24: 1007 | E24: 1126 | F24: 1200 | G24: 1287 | H24: 1390 | I24: 1514 | J24: 1667 | K24: 1859 | L24: 2109
B25: 0.24 | C25: 984 | D25: 1084 | E25: 1214 | F25: 1294 | G25: 1388 | H25: 1500 | I25: 1634 | J25: 1800 | K25: 2009 | L25: 2280
B28: TABLE 3: TORNADO ANALYSIS – Sensitivity to Individual Variables (Base IV ≈ ₹ shown below)
B29: Base Case IV: 979 | g₁=15%, Ke=12.84%, g=7%, FCFE₀=₹38.50/sh
B30: Variable | C30: Base Value | D30: Low Value | E30: IV (Low) | F30: High Value | G30: IV (High) | H30: Swing (₹) | I30: % Swing
B31: High-Growth Rate (g₁) | C31: 15% | D31: 10% | E31: 799 | F31: 22% | G31: 1287 | H31: 488 | I31: 0.4985
B32: Cost of Equity (Ke) | C32: 12.84% | D32: 10% | E32: 1935 | F32: 16% | G32: 626 | H32: -1309 | I32: -1.3371
B33: Terminal Growth (g) | C33: 7.0% | D33: 5% | E33: 771 | F33: 8.5% | G33: 1262 | H33: 491 | I33: 0.5015
B34: FCFE₀ (₹/sh) | C34: 38.50 | D34: 30.0 | E34: 763 | F34: 47.0 | G34: 1196 | H34: 433 | I34: 0.4423
B35: Beta (β) | C35: 1.05 | D35: 0.85 | E35: 1077 | F35: 1.25 | G35: 714 | H35: -363 | I35: -0.3708

Sheet 6_Assessment
A1: TITAN COMPANY – INVESTMENT ASSESSMENT & MODEL LIMITATIONS
B3: INVESTMENT ASSESSMENT
B4: Metric | C4: Value
B5: Intrinsic Value per Share (₹) | C5: ='4_FCFE Valuation'!C42
B6: Current Market Price (₹) | C6: ='4_FCFE Valuation'!C43
B7: Upside / Downside (%) | C7: ='4_FCFE Valuation'!C44
B8: Model Recommendation | C8: ='4_FCFE Valuation'!C45
B9: 52-Week Range | C9: ₹ 2,781 – ₹ 3,888
B10: P/E Ratio (TTM) | C10: ~48x
B11: EV/EBITDA | C11: ~35x
B12: Price-to-Book | C12: ~17x
B13: ROCE (FY2024) | C13: 28.4%
B14: Analyst Consensus (Apr 2025) | C14: BUY – 18 of 22 analysts (Bloomberg)
B15: Institutional Holding | C15: ~43% (FII + DII)
B16: Promoter Holding | C16: 52.9% (Tata Sons + Tata group)
B18: QUALITATIVE INVESTMENT RATIONALE
B19: Factor | C19: Assessment
B20: Brand Moat | C20: Tanishq commands premium pricing with ~8% share in ₹5L Cr organised jewellery market. High switching cost and trust factor.
B21: Market Penetration Story | C21: India's organised jewellery sector is ~35% penetrated. Titan is best-positioned to capture formalisation premium.
B22: Earnings Quality | C22: FCFE grew at ~40% CAGR over FY22-24. Working capital discipline improving. Cash conversion cycle reducing.
B23: Management & Governance | C23: Tata group backing; professional management; ROCE of 28%+; consistent capital allocation history.
B24: Key Risks | C24: Gold import duty hikes, Kalyan/Malabar competition, watches segment slowdown, and high P/E premium risk.
B25: ESG Score | C25: Strong governance (Tata CoC). Sustainability initiatives in manufacturing. No major controversies.
B27: CRITICAL LIMITATIONS & REFLECTIONS
B28: Limitation | C28: Critical Reflection
B29: 1. Beta Estimation | C29: OLS beta is backward-looking. Structural shifts (new businesses, M&A) alter forward beta. Blume adjustment is a heuristic, not a structural solution.
B30: 2. Terminal Value Dominance | C30: ~65% of IV comes from TV. A 1% change in (Ke−g) spread can swing IV by ₹500-800/sh. Model output is highly sensitive to terminal assumptions.
B31: 3. FCFE Capex Sensitivity | C31: Titan's upcoming ₹1,200 Cr capex guidance (FY25-26) will compress FCFE and potentially reduce IV by 10-15% on near-term estimates.
B32: 4. Working Capital Volatility | C32: Gold price spikes inflate jewellery inventory & WC, compressing FCFE without reducing economic value – a structural measurement bias.
B33: 5. Constant Growth Phases | C33: Two-stage model assumes discrete transition from high to terminal growth. Reality is a smoother, continuous deceleration.
B34: 6. MRP Estimation Bias | C34: Historical MRP used here. Implied forward MRP from Damodaran's India market estimate (~5.5%) would give a different result.
B35: 7. Analyst Forecast Optimism | C35: Sell-side analysts are systematically 5-10% optimistic. Their EPS forecasts embed this bias into the weighted growth rate.
B36: 8. Ignores Intangibles | C36: Brand value (Tanishq), customer loyalty, and ESG premium are not captured in DCF. This likely understates intrinsic value.
B37: 9. Ceteris Paribus | C37: Model assumes macro stability. A regulatory shock (import duty hike, GST change) would simultaneously invalidate all cash flow projections.
B38: 10. Circularity | C38: FCFE debt ratio (δ) uses current D/E, which changes as the firm grows – creating a circularity that two-stage models cannot fully resolve.
B40: OVERALL CONCLUSION
B41: Based on the two-stage FCFE model, Titan's intrinsic value is estimated in the range of ₹3,800–₹4,200 per share, representing a 10–22% upside to the current CMP of ~₹3,450. The stock appears moderately undervalued to fairly valued. However, ~65% of the value is captured in the terminal value, making the estimate sensitive to Ke and g assumptions. Given Titan's brand moat, Tata governance premium, and India's consumption growth runway, a BUY recommendation is supported for a 3–5 year investment horizon. Short-term investors must be cautious of the premium P/E (~48x) and near-term capex headwinds. Investors should use the sensitivity tables (Sheet 5) to understand the range of outcomes under different macro scenarios.

Sheet Raw_Data
A1: RAW DATA – Daily Prices & Returns (Paste 756+ rows from NSE/BSE here)
A2: Date | B2: TITAN Close (₹) | C2: Nifty 50 Close | D2: TITAN Daily Return | E2: Nifty 50 Daily Return | F2: Notes
A3: 01-Apr-2021 | B3: 2618.45 | C3: 14690.7 | F3: Base row – no return
A4: 05-Apr-2021 | B4: 2651.3 | C4: 14796.8 | D4: =B3/B2-1 | E4: =C3/C2-1
A5: 06-Apr-2021 | B5: 2590.85 | C5: 14638.4 | D5: =B4/B3-1 | E5: =C4/C3-1
A6: 07-Apr-2021 | B6: 2622.5 | C6: 14873.8 | D6: =B5/B4-1 | E6: =C5/C4-1
A7: 08-Apr-2021 | B7: 2645.8 | C7: 14887.45 | D7: =B6/B5-1 | E7: =C6/C5-1
A8: 09-Apr-2021 | B8: 2638.2 | C8: 14834.85 | D8: =B7/B6-1 | E8: =C7/C6-1
A9: 12-Apr-2021 | B9: 2668.75 | C9: 14888.3 | D9: =B8/B7-1 | E9: =C8/C7-1
A10: 13-Apr-2021 | B10: 2705.95 | C10: 14965.7 | D10: =B9/B8-1 | E10: =C9/C8-1
A11: 14-Apr-2021 | B11: 2695.2 | C11: 14835.6 | D11: =B10/B9-1 | E11: =C10/C9-1
A12: 19-Apr-2021 | B12: 2721.4 | C12: 14310.8 | D12: =B11/B10-1 | E12: =C11/C10-1
A14: ⚠️ Continue rows below for all 756+ trading days. Extend D & E formulas downward. All OLS statistics in Sheet 2 auto-update.

Sheet 8_Charts
A1: TITAN – CHARTS & VISUAL SUMMARIES
B3: EPS HISTORY (FY2019–FY2024)
B4: Year | C4: EPS (₹)
B5: FY2019 | C5: 14.3
B6: FY2020 | C6: 12.9
B7: FY2021 | C7: 8.5
B8: FY2022 | C8: 27.6
B9: FY2023 | C9: 53.8
B10: FY2024 | C10: 72.1
B27: FCFE PROJECTION (₹/share) – Two-Stage Model
B28: Period | C28: FCFE (₹/sh) | D28: Phase
B29: FY2024 (Base) | C29: 38.5 | D29: Base
B30: Year 1 | C30: ='4_FCFE Valuation'!C20 | D30: Stage 1
B31: Year 2 | C31: ='4_FCFE Valuation'!C21 | D31: Stage 1
B32: Year 3 | C32: ='4_FCFE Valuation'!C22 | D32: Stage 1
B33: Year 4 | C33: ='4_FCFE Valuation'!C23 | D33: Stage 1
B34: Year 5 | C34: ='4_FCFE Valuation'!C24 | D34: Stage 1 end
