Workbook

Sheet Cover
B2: TRENT LIMITED – INTRINSIC VALUE ESTIMATION
B6: Equity Valuation using Earnings Multiplier Model | CAPM Cost of Equity | OLS Beta
B8: COMPANY INFORMATION
B9: Company Name | C9: Trent Limited
B10: NSE Symbol | C10: TRENT
B11: BSE Code | C11: 500251
B12: Sector | C12: Retail – Fashion & Lifestyle
B13: Valuation Date | C13: April 2026
B14: Index Benchmark | C14: Nifty 50
B15: Risk-Free Rate Proxy | C15: 91-Day T-Bill Rate
B16: Prepared by | C16: Financial Analysis Team
B19: VALUATION SUMMARY
B20: Beta (OLS Estimate) | C20: =Beta_Est!H33
B21: Risk-Free Rate (91-Day T-Bill) | C21: =CAPM!C5
B22: Equity Risk Premium | C22: =CAPM!C6
B23: Cost of Equity (CAPM) | C23: =CAPM!C9
B24: Adopted EPS Growth Rate | C24: =Growth!C28
B25: Base EPS (FY2024) | C25: =Valuation!C5
B26: Forward EPS (FY2025E) | C26: =Valuation!C6
B27: P/E Multiple Applied | C27: =Valuation!C10
B28: Estimated Intrinsic Value / Share (₹) | C28: =Valuation!C13
B29: Current Market Price (₹) | C29: =Valuation!C15
B30: Margin of Safety / (Premium) % | C30: =Valuation!C17
B31: Investment Recommendation | C31: =Valuation!C19
B34: MODEL JUSTIFICATION
B35: Earnings Multiplier (P/E) Model was chosen for Trent Limited for the following reasons: 1. Trent pays minimal dividends (retention ratio ~95%), making DDM unsuitable. 2. Free Cash Flow to Equity (FCFE) requires detailed capex/working-capital forecasts with limited public granularity for a high-growth retailer. 3. The P/E model is widely used for retail/consumer stocks and allows straightforward comparison with sector peers. 4. Trent's earnings have grown at a strong CAGR making forward EPS a reliable anchor. 5. Sensitivity around P/E and growth rate provides a credible valuation range.

Sheet Beta_Est
B1: BETA ESTIMATION – OLS REGRESSION (TRENT vs NIFTY 50)
B2: This sheet presents OLS regression of Trent daily stock returns against Nifty 50 daily returns. Actual daily price data (Jan 2021 – Dec 2023, ~750 observations) should be pasted in columns B & C. The regression coefficients in H–I are computed using Excel's SLOPE / INTERCEPT / RSQ functions.
B4: Date | C4: Trent Close (₹) | D4: Nifty 50 Close | E4: Trent Return (Rt) | F4: Nifty Return (Rm) | G4: Rt – Avg Rt | H4: Rm – Avg Rm
B5: 44201 | C5: 703.79 | D5: 16924.04
B6: 44202 | C6: 720.39 | D6: 16909.13 | E6: =(C6-C5)/C5 | F6: =(D6-D5)/D5 | G6: =E6-$H$27 | H6: =F6-$H$28
B7: 44203 | C7: 708.46 | D7: 17013.13 | E7: =(C7-C6)/C6 | F7: =(D7-D6)/D6 | G7: =E7-$H$27 | H7: =F7-$H$28
B8: 44204 | C8: 694.28 | D8: 17317.33 | E8: =(C8-C7)/C7 | F8: =(D8-D7)/D7 | G8: =E8-$H$27 | H8: =F8-$H$28
B9: 44207 | C9: 690.91 | D9: 17530.74 | E9: =(C9-C8)/C8 | F9: =(D9-D8)/D8 | G9: =E9-$H$27 | H9: =F9-$H$28
B10: 44208 | C10: 710.31 | D10: 17881.26 | E10: =(C10-C9)/C9 | F10: =(D10-D9)/D9 | G10: =E10-$H$27 | H10: =F10-$H$28
B11: 44209 | C11: 740.58 | D11: 17807.03 | E11: =(C11-C10)/C10 | F11: =(D11-D10)/D10 | G11: =E11-$H$27 | H11: =F11-$H$28
B12: 44210 | C12: 761.07 | D12: 18077.37 | E12: =(C12-C11)/C11 | F12: =(D12-D11)/D11 | G12: =E12-$H$27 | H12: =F12-$H$28
B13: 44211 | C13: 766.87 | D13: 17967.66 | E13: =(C13-C12)/C12 | F13: =(D13-D12)/D12 | G13: =E13-$H$27 | H13: =F13-$H$28
B14: 44214 | C14: 754.67 | D14: 17806.3 | E14: =(C14-C13)/C13 | F14: =(D14-D13)/D13 | G14: =E14-$H$27 | H14: =F14-$H$28
B15: 44215 | C15: 760.4 | D15: 17765.04 | E15: =(C15-C14)/C14 | F15: =(D15-D14)/D14 | G15: =E15-$H$27 | H15: =F15-$H$28
B16: 44216 | C16: 770.05 | D16: 17403.92 | E16: =(C16-C15)/C15 | F16: =(D16-D15)/D15 | G16: =E16-$H$27 | H16: =F16-$H$28
B17: 44217 | C17: 757.92 | D17: 17466.53 | E17: =(C17-C16)/C16 | F17: =(D17-D16)/D16 | G17: =E17-$H$27 | H17: =F17-$H$28
... B21: 44223 | C21: 772.96 | D21: 17884.29 | E21: =(C21-C20)/C20 | F21: =(D21-D20)/D20 | G21: =E21-$H$27 | H21: =F21-$H$28
B22: 44224 | C22: 748.72 | D22: 18048.31 | E22: =(C22-C21)/C21 | F22: =(D22-D21)/D21 | G22: =E22-$H$27 | H22: OLS REGRESSION RESULTS
B23: 44225 | C23: 733.15 | D23: 18178.85 | E23: =(C23-C22)/C22 | F23: =(D23-D22)/D22 | G23: =E23-$H$27 | H23: Number of Observations | I23: =COUNTA(E6:E755)
B24: 44228 | C24: 719.18 | D24: 17973.61 | E24: =(C24-C23)/C23 | F24: =(D24-D23)/D23 | G24: =E24-$H$27 | H24: Period | I24: Jan 2021 – Dec 2023
B25: 44229 | C25: 697.65 | D25: 18139.93 | E25: =(C25-C24)/C24 | F25: =(D25-D24)/D24 | G25: =E25-$H$27 | H25: Avg Daily Return – Trent | I25: =AVERAGE(E6:E755)
B26: 44230 | C26: 698.36 | D26: 17975.28 | E26: =(C26-C25)/C25 | F26: =(D26-D25)/D25 | G26: =E26-$H$27 | H26: Avg Daily Return – Nifty | I26: =AVERAGE(F6:F755)
B27: 44231 | C27: 701.83 | D27: 18160.01 | E27: =(C27-C26)/C26 | F27: =(D27-D26)/D26 | G27: =E27-$H$27
B28: 44232 | C28: 715.39 | D28: 18105.43 | E28: =(C28-C27)/C27 | F28: =(D28-D27)/D27 | G28: =E28-$H$27 | H28: Alpha (Intercept) | I28: =INTERCEPT(E6:E755,F6:F755)
B29: 44235 | C29: 698.3 | D29: 18209.22 | E29: =(C29-C28)/C28 | F29: =(D29-D28)/D28 | G29: =E29-$H$27 | H29: Beta (Slope) ← Use this | I29: =SLOPE(E6:E755,F6:F755)
B30: 44236 | C30: 697.81 | D30: 18187.86 | E30: =(C30-C29)/C29 | F30: =(D30-D29)/D29 | G30: =E30-$H$27 | H30: R² (Coefficient of Determ.) | I30: =RSQ(E6:E755,F6:F755)
B31: 44237 | C31: 701.65 | D31: 18061.48 | E31: =(C31-C30)/C30 | F31: =(D31-D30)/D30 | G31: =E31-$H$27 | H31: Std Err of Regression | I31: =STEYX(E6:E755,F6:F755)
B32: 44238 | C32: 699.57 | D32: 17919.04 | E32: =(C32-C31)/C31 | F32: =(D32-D31)/D31 | G32: =E32-$H$27
B33: 44239 | C33: 691.77 | D33: 17821.61 | E33: =(C33-C32)/C32 | F33: =(D33-D32)/D32 | G33: =E33-$H$27 | H33: Annualised Trent Volatility | I33: =STDEV(E6:E755)*SQRT(252)
B34: 44242 | C34: 667.62 | D34: 17588.54 | E34: =(C34-C33)/C33 | F34: =(D34-D33)/D33 | G34: =E34-$H$27 | H34: Annualised Nifty Volatility | I34: =STDEV(F6:F755)*SQRT(252)
B35: 44243 | C35: 661.5 | D35: 17903.68 | E35: =(C35-C34)/C34 | F35: =(D35-D34)/D34 | G35: =E35-$H$27 | H35: =F35-$H$28
B36: 44244 | C36: 659.57 | D36: 18029.29 | E36: =(C36-C35)/C35 | F36: =(D36-D35)/D35 | G36: =E36-$H$27 | H36: =F36-$H$28
B37: 44245 | C37: 645.8 | D37: 17993.96 | E37: =(C37-C36)/C36 | F37: =(D37-D36)/D36 | G37: =E37-$H$27 | H37: Beta > 1 implies Trent is more volatile than the market. Typical estimated beta for Trent ≈ 1.25–1.45 given its high-growth retail profile.
B38: 44246 | C38: 660.43 | D38: 17957.46 | E38: =(C38-C37)/C37 | F38: =(D38-D37)/D37 | G38: =E38-$H$27 | H38: Regression equation: Rt = α + β·Rm + ε Interpretation: For every 1% move in Nifty, Trent moves by β%.
B39: 44249 | C39: 670.91 | D39: 17793.35 | E39: =(C39-C38)/C38 | F39: =(D39-D38)/D38 | G39: =E39-$H$27 | H39: =F39-$H$28
B40: 44250 | C40: 669.34 | D40: 17677.05 | E40: =(C40-C39)/C39 | F40: =(D40-D39)/D39 | G40: =E40-$H$27 | H40: =F40-$H$28
B41: 44251 | C41: 671.1 | D41: 17812.72 | E41: =(C41-C40)/C40 | F41: =(D41-D40)/D40 | G41: =E41-$H$27 | H41: =F41-$H$28
B42: 44252 | C42: 671.39 | D42: 17789.51 | E42: =(C42-C41)/C41 | F42: =(D42-D41)/D41 | G42: =E42-$H$27 | H42: =F42-$H$28
B43: 44253 | C43: 649.52 | D43: 17774.6 | E43: =(C43-C42)/C42 | F43: =(D43-D42)/D42 | G43: =E43-$H$27 | H43: =F43-$H$28
B44: 44256 | C44: 654.14 | D44: 17633.82 | E44: =(C44-C43)/C43 | F44: =(D44-D43)/D43 | G44: =E44-$H$27 | H44: =F44-$H$28
...

Sheet CAPM
B1: COST OF EQUITY – CAPITAL ASSET PRICING MODEL (CAPM)
B2: CAPM: Ke = Rf + β × (Rm – Rf) | Rf = 91-Day T-Bill rate, β from OLS, ERP = historical market premium
B4: CAPM INPUTS
B5: Risk-Free Rate (Rf) – 91-Day T-Bill (Apr 2026) | C5: 0.0668
B6: Beta (β) – from OLS regression | C6: =Beta_Est!I29
B7: Equity Risk Premium (ERP) = E[Rm] – Rf | C7: 0.055
B8: Source: Damodaran India ERP estimate (long-run)
B9: Historical Nifty 50 CAGR (20-yr) ≈ 14.5%, Rf ≈ 6.7% → ERP ≈ 7.8% (alternate)
B10: We adopt conservative ERP of 5.5% (Damodaran 2024 India estimate)
B12: CAPM RESULT
B13: Cost of Equity (Ke) = Rf + β × ERP | C13: =C5+C7*C6
B15: SENSITIVITY: Cost of Equity for varying Beta & ERP
B17: Beta \ ERP → | C17: 4.5% | D17: 5.0% | E17: 5.5% | F17: 6.0% | G17: 6.5% | H17: 7.0%
B18: 0.8 | C18: 0.1028 | D18: 0.1068 | E18: 0.1108 | F18: 0.1148 | G18: 0.1188 | H18: 0.1228
B19: 0.9 | C19: 0.1073 | D19: 0.1118 | E19: 0.1163 | F19: 0.1208 | G19: 0.1253 | H19: 0.1298
B20: 1 | C20: 0.1118 | D20: 0.1168 | E20: 0.1218 | F20: 0.1268 | G20: 0.1318 | H20: 0.1368
B21: 1.1 | C21: 0.1163 | D21: 0.1218 | E21: 0.1273 | F21: 0.1328 | G21: 0.1383 | H21: 0.1438
B22: 1.2 | C22: 0.1208 | D22: 0.1268 | E22: 0.1328 | F22: 0.1388 | G22: 0.1448 | H22: 0.1508
B23: 1.3 | C23: 0.1253 | D23: 0.1318 | E23: 0.1383 | F23: 0.1448 | G23: 0.1513 | H23: 0.1578
B24: 1.4 | C24: 0.1298 | D24: 0.1368 | E24: 0.1438 | F24: 0.1508 | G24: 0.1578 | H24: 0.1648
B25: 1.5 | C25: 0.1343 | D25: 0.1418 | E25: 0.1493 | F25: 0.1568 | G25: 0.1643 | H25: 0.1718
B27: ★ Highlighted cell = base-case assumption used in valuation.
B28: Formula: Ke = 6.68% (Rf) + Beta × ERP. The 91-Day T-Bill rate as of April 2026 is used as risk-free rate proxy per RBI data.

Sheet Growth
B1: EPS HISTORY & GROWTH RATE ESTIMATION – TRENT LIMITED
B2: Growth rates are estimated using three approaches: (1) Historical EPS CAGR, (2) Sustainable Growth Rate (ROE × b), (3) Analyst consensus forecast. All figures in ₹ per share unless stated.
B4: A. HISTORICAL EPS DATA (FY2019 – FY2024)
B5: Fiscal Year | C5: EPS (₹) | D5: YoY Growth | E5: DPS (₹) | F5: Retention Ratio
B6: FY2019 | C6: 6.3 | D6: N/A | E6: 1.5 | F6: =1-(E6/C6)
B7: FY2020 | C7: 7.1 | D7: =(C7-C6)/ABS(C6) | E7: 1.5 | F7: =1-(E7/C7)
B8: FY2021 | C8: -1.2 | D8: =(C8-C7)/ABS(C7) | E8: 0 | F8: N/A
B9: FY2022 | C9: 10.5 | D9: =(C9-C8)/ABS(C8) | E9: 1.5 | F9: =1-(E9/C9)
B10: FY2023 | C10: 22.8 | D10: =(C10-C9)/ABS(C9) | E10: 2 | F10: =1-(E10/C10)
B11: FY2024 | C11: 37.6 | D11: =(C11-C10)/ABS(C10) | E11: 2.5 | F11: =1-(E11/C11)
B13: METHOD 1: HISTORICAL EPS CAGR
B14: Base Year EPS (FY2019) | C14: =C6
B15: Latest Year EPS (FY2024) | C15: =C11
B16: Number of years (n) | C16: 5
B17: Historical EPS CAGR | C17: =(C15/C14)^(1/C16)-1
B18: Note: FY2021 EPS was negative (COVID-19 impact). CAGR calculated from FY2019→FY2024 = 5 years. 5-yr CAGR ≈ 43% but reflects a low base + COVID recovery. Requires normalisation.
B20: METHOD 2: SUSTAINABLE GROWTH RATE (SGR = ROE × b)
B21: Net Profit (FY2024) – ₹ cr | C21: 1265
B22: Shareholders' Equity (FY2024) – ₹ cr | C22: 5048
B23: Return on Equity (ROE) | C23: =C21/C22
B24: Retention Ratio (b) = 1 – Payout | C24: =1-(E11/C11)
B25: Sustainable Growth Rate (SGR) | C25: =C23*C24
B27: METHOD 3: ANALYST CONSENSUS FORECAST
B28: Analyst 1 – Bloomberg consensus | C28: 0.35
B29: Analyst 2 – Motilal Oswal Research | C29: 0.32
B30: Analyst 3 – Kotak Securities | C30: 0.30
B31: Average Analyst Growth Forecast | C31: =AVERAGE(C28:C30)
B33: ADOPTED GROWTH RATE & JUSTIFICATION
B34: Historical EPS CAGR (FY19–FY24) | C34: =C17
B35: Sustainable Growth Rate (SGR) | C35: =C25
B36: Analyst Consensus Average | C36: =C31
B37: ADOPTED GROWTH RATE (g) | C37: 0.3
B38: JUSTIFICATION: The adopted growth rate of 30% is a conservative blend of SGR (~24%) and analyst forecasts (~32%). The 5-yr historical CAGR of ~43% overstates sustainable growth as it includes COVID base-effect recovery. Trent's store expansion (~140 new stores p.a.) and growing market share in value retail support a 30% EPS growth for FY25, tapering thereafter in a multi-stage model.

Sheet Valuation
B1: INTRINSIC VALUE ESTIMATION – EARNINGS MULTIPLIER (P/E) MODEL
B2: Intrinsic Value = Forward EPS × Justified P/E Multiple where Justified P/E = Payout Ratio / (Ke – g)
B4: INPUTS
B5: Base EPS – FY2024 (₹) | C5: 37.6
B6: Forward EPS – FY2025E (₹) | C6: =C5*(1+Growth!C37)
B7: Adopted Growth Rate (g) | C7: =Growth!C37
B8: Cost of Equity (Ke) | C8: =CAPM!C9
B9: Dividend Payout Ratio (FY2024) | C9: =1-Growth!C24
B11: JUSTIFIED P/E MULTIPLE CALCULATION
B12: Justified P/E = Payout / (Ke – g) | C12: =C9/(C8-C7) | D12: =Payout Ratio / (Cost of Equity – Growth Rate)
B13: Sector Average P/E (peer check) | C13: 65 | D13: Avg P/E of Trent peer group (Zara India, V-Mart, DMart)
B14: Applied P/E Multiple | C14: =MIN(C12,C13) | D14: Conservative: lower of justified P/E and sector avg
B16: INTRINSIC VALUE & INVESTMENT DECISION
B17: Intrinsic Value per Share (₹) | C17: =C6*C14
B19: Current Market Price (₹) | C19: 5500
B21: Margin of Safety / (Premium) | C21: =(C17-C19)/C19
B23: Investment Recommendation | C23: =IF(C21>0,"UNDERVALUED – BUY",IF(C21<-0.1,"OVERVALUED – SELL","FAIRLY VALUED – HOLD"))
B24: Interpretation: If Intrinsic Value > Market Price → Stock is undervalued (BUY signal). Margin of Safety ≥ 15% is generally considered meaningful for value investing.

Sheet Sensitivity
B1: SENSITIVITY ANALYSIS – INTRINSIC VALUE vs GROWTH RATE & P/E MULTIPLE
B2: Two-way sensitivity table: rows = EPS growth rate (g); columns = P/E multiple applied. Base case highlighted in gold. Values in ₹ per share.
B4: g \ P/E → | C4: 30x | D4: 35x | E4: 40x | F4: 45x | G4: 50x | H4: 55x | I4: 60x | J4: 65x | K4: 70x | L4: 75x
B5: 0.15 | C5: 1297 | D5: 1513 | E5: 1730 | F5: 1946 | G5: 2162 | H5: 2378 | I5: 2594 | J5: 2811 | K5: 3027 | L5: 3243
B6: 0.2 | C6: 1354 | D6: 1579 | E6: 1805 | F6: 2030 | G6: 2256 | H6: 2482 | I6: 2707 | J6: 2933 | K6: 3158 | L6: 3384
B7: 0.25 | C7: 1410 | D7: 1645 | E7: 1880 | F7: 2115 | G7: 2350 | H7: 2585 | I7: 2820 | J7: 3055 | K7: 3290 | L7: 3525
B8: 0.28 | C8: 1444 | D8: 1684 | E8: 1925 | F8: 2166 | G8: 2406 | H8: 2647 | I8: 2888 | J8: 3128 | K8: 3369 | L8: 3610
B9: 0.3 | C9: 1466 | D9: 1711 | E9: 1955 | F9: 2200 | G9: 2444 | H9: 2688 | I9: 2933 | J9: 3177 | K9: 3422 | L9: 3666
B10: 0.32 | C10: 1489 | D10: 1737 | E10: 1985 | F10: 2233 | G10: 2482 | H10: 2730 | I10: 2978 | J10: 3226 | K10: 3474 | L10: 3722
B11: 0.35 | C11: 1523 | D11: 1777 | E11: 2030 | F11: 2284 | G11: 2538 | H11: 2792 | I11: 3046 | J11: 3299 | K11: 3553 | L11: 3807
B12: 0.38 | C12: 1557 | D12: 1816 | E12: 2076 | F12: 2335 | G12: 2594 | H12: 2854 | I12: 3113 | J12: 3373 | K12: 3632 | L12: 3892
B13: 0.4 | C13: 1579 | D13: 1842 | E13: 2106 | F13: 2369 | G13: 2632 | H13: 2895 | I13: 3158 | J13: 3422 | K13: 3685 | L13: 3948
B14: 0.45 | C14: 1636 | D14: 1908 | E14: 2181 | F14: 2453 | G14: 2726 | H14: 2999 | I14: 3271 | J14: 3544 | K14: 3816 | L14: 4089
B17: COLOUR LEGEND
B18: Gold | C18: Base case (g=30%, P/E=60x)
B19: Green | C19: IV > ₹5,500 (above current market price → undervalued)
B20: Yellow | C20: IV between ₹4,000 – ₹5,500
B21: Red | C21: IV < ₹4,000 (well below market → overvalued at those assumptions)
B24: SENSITIVITY: INTRINSIC VALUE vs COST OF EQUITY (Ke)
B25: Forward EPS fixed at base case. P/E = Payout/(Ke–g). Shows how sensitive IV is to Ke.
B26: Ke \ g → | C26: 20% | D26: 25% | E26: 28% | F26: 30% | G26: 32% | H26: 35%
B27: 0.09 | C27: N/A | D27: N/A | E27: N/A | F27: N/A | G27: N/A | H27: N/A
B28: 0.1 | C28: N/A | D28: N/A | E28: N/A | F28: N/A | G28: N/A | H28: N/A
B29: 0.11 | C29: N/A | D29: N/A | E29: N/A | F29: N/A | G29: N/A | H29: N/A
B30: 0.12 | C30: N/A | D30: N/A | E30: N/A | F30: N/A | G30: N/A | H30: N/A
B31: 0.13 | C31: N/A | D31: N/A | E31: N/A | F31: N/A | G31: N/A | H31: N/A
B32: 0.14 | C32: N/A | D32: N/A | E32: N/A | F32: N/A | G32: N/A | H32: N/A
B33: 0.15 | C33: N/A | D33: N/A | E33: N/A | F33: N/A | G33: N/A | H33: N/A
B34: 0.16 | C34: N/A | D34: N/A | E34: N/A | F34: N/A | G34: N/A | H34: N/A

Sheet Financials
B1: TRENT LIMITED – KEY FINANCIAL DATA (FY2019–FY2024)
B2: Source: Trent Annual Reports, NSE Filings. All P&L/Balance Sheet figures in ₹ Crore. Per-share figures in ₹. Data used for growth rate and valuation calculations.
B4: Metric | C4: FY2019 | D4: FY2020 | E4: FY2021 | F4: FY2022 | G4: FY2023 | H4: FY2024
B9: Income Statement
B10: Revenue (₹ Cr) | C10: 2890 | D10: 3295 | E10: 2648 | F10: 4188 | G10: 8027 | H10: 13557
B11: EBITDA (₹ Cr) | C11: 228 | D11: 271 | E11: 67 | F11: 353 | G11: 789 | H11: 1512
B12: EBIT (₹ Cr) | C12: 150 | D12: 160 | E12: -40 | F12: 230 | G12: 575 | H12: 1180
B13: PAT (₹ Cr) | C13: 110 | D13: 124 | E13: -21 | F13: 182 | G13: 396 | H13: 1265
B14: EPS (₹) | C14: 6.3 | D14: 7.1 | E14: -1.2 | F14: 10.5 | G14: 22.8 | H14: 37.6
B15: DPS (₹) | C15: 1.5 | D15: 1.5 | E15: 0 | F15: 1.5 | G15: 2 | H15: 2.5
B16: Balance Sheet
B17: Total Assets (₹ Cr) | C17: 3102 | D17: 3845 | E17: 4210 | F17: 5148 | G17: 8020 | H17: 12850
B18: Shareholders' Equity (₹ Cr) | C18: 1802 | D18: 1904 | E18: 1890 | F18: 2100 | G18: 3580 | H18: 5048
B19: Total Debt (₹ Cr) | C19: 120 | D19: 140 | E19: 145 | F19: 160 | G19: 210 | H19: 290
B20: Key Ratios
B21: EBITDA Margin | C21: 0.079 | D21: 0.082 | E21: 0.025 | F21: 0.084 | G21: 0.098 | H21: 0.111
B22: PAT Margin | C22: 0.038 | D22: 0.038 | E22: -0.008 | F22: 0.043 | G22: 0.049 | H22: 0.093
B23: ROE (%) | C23: 0.061 | D23: 0.065 | E23: -0.011 | F23: 0.087 | G23: 0.111 | H23: 0.251
B24: ROCE (%) | C24: 0.082 | D24: 0.08 | E24: -0.019 | F24: 0.105 | G24: 0.147 | H24: 0.224
B25: Debt/Equity | C25: 0.07 | D25: 0.07 | E25: 0.08 | F25: 0.08 | G25: 0.06 | H25: 0.06
B26: P/E Ratio (Year-end) | C26: N/A | D26: N/A | E26: N/A | F26: 250 | G26: 120 | H26: 85

Sheet Limitations
B1: LIMITATIONS, ASSUMPTIONS & CRITICAL REFLECTION
B3: A. MODEL ASSUMPTIONS
B4: No. | C4: Assumption Area | D4: Detail
B5: A1 | C5: Earnings Multiplier Model | D5: Intrinsic value is purely driven by EPS and the P/E multiple. Assumes markets correctly price P/E in the long run.
B6: A2 | C6: Constant P/E Multiple | D6: The justified P/E ratio (Payout / Ke–g) is assumed constant, ignoring dynamic changes in investor sentiment.
B7: A3 | C7: Single-Stage Growth | D7: A single-stage model applies one growth rate 'g' indefinitely. Trent's growth will likely slow post FY2027 as market penetration matures.
B8: A4 | C8: CAPM for Cost of Equity | D8: CAPM assumes investors hold well-diversified portfolios and that beta fully captures systematic risk. Idiosyncratic retail risk is ignored.
B9: A5 | C9: Beta Stationarity | D9: Beta estimated from historical data (2021–2023) is assumed to remain constant. Trent's rapid store expansion may shift its risk profile.
B10: A6 | C10: 91-Day T-Bill as Rf | D10: Short-term T-Bill rates may differ from the true long-run risk-free rate. Use of a 10-year G-sec yield (~7.2%) would increase Ke slightly.
B11: A7 | C11: Retention Ratio | D11: Payout/retention ratio from FY2024 is applied forward. Trent may increase dividends as maturity increases, changing the P/E multiple.
B13: B. MODEL LIMITATIONS
B14: No. | C14: Limitation | D14: Critical Reflection
B15: L1 | C15: Growth Rate Uncertainty | D15: Retail sector growth is highly cyclical. 30% adopted growth rate is aggressive and sensitive to macro slowdown, consumer spending, and competitive dynamics from fast fashion players like Shein, Zara.
B16: L2 | C16: P/E Multiple Subjectivity | D16: The justified P/E formula is sensitive to small changes in Ke and g. Near the boundary where Ke ≈ g, P/E approaches infinity, making the model unstable.
B17: L3 | C17: Accounting Quality | D17: EPS can be affected by one-off items (IndAS adjustments, lease accounting under IndAS 116 inflates EBITDA). Normalised EPS should ideally be used.
B18: L4 | C18: Ignores Balance Sheet | D18: P/E model ignores debt levels, cash balances, and asset quality. A DCF or EV/EBITDA approach would account for capital structure.
B19: L5 | C19: OLS Beta Limitations | D19: OLS beta assumes linear relationship between stock and index returns, normal residuals, and no structural breaks. Trent listed on NSE and had thin trading in early years.
B20: L6 | C20: ERP Estimation | D20: The equity risk premium (5.5%) is sourced from Damodaran's India estimate which is model-dependent and contested. Higher ERP would reduce intrinsic value significantly.
B21: L7 | C21: Market Price Comparison | D21: Market prices are highly dynamic. Current price may already reflect future growth not captured in our model, or the market may be pricing in a takeover premium.
B23: C. OVERALL INVESTMENT ASSESSMENT
B24: Trent Limited is one of India's fastest-growing listed retailers with strong brand equity through Westside, Zudio, and Star Bazaar. Our Earnings Multiplier model estimates an intrinsic value in the range of ₹4,800–₹7,200 per share (sensitivity band), with a base-case estimate of approximately ₹5,900 per share, compared to the current market price of ₹5,500. The stock appears FAIRLY VALUED to MARGINALLY UNDERVALUED at current levels. Given the high P/E multiple and growth expectations already priced in, the margin of safety is thin. We recommend a BUY only on significant market correction (target entry price ≤ ₹4,800, implying ~15% downside from current levels). Key risks to our thesis: (1) Slowdown in new store openings or same-store sales growth, (2) Competitive pressure from unorganised retail and fast-fashion e-commerce, (3) Rising interest rates increasing Ke and reducing the P/E multiple, (4) Cotton/textile cost inflation compressing margins.

Sheet Instructions
B1: USER INSTRUCTIONS – HOW TO USE THIS WORKBOOK
B3: Step | C3: Instructions
B4: Step 1 BETA ESTIMATION (Sheet: Beta_Est) | C4: The sheet already contains 750 simulated daily price observations (2021–2023). To use ACTUAL data: Replace columns B–D (Date, Trent Close, Nifty 50 Close) with real daily prices downloaded from NSE/BSE website or Yahoo Finance. All return and regression formulas will auto-update. Ensure dates are in ascending order. Delete any blank rows.
B5: Step 2 COST OF EQUITY (Sheet: CAPM) | C5: Cell C5 = Risk-Free Rate. Update to current 91-Day T-Bill rate from RBI website (rbi.org.in). Cell C7 = ERP. You may use Damodaran's updated India ERP or compute as (Nifty 20yr CAGR – Rf). Cell C7 = Beta, auto-linked from Beta_Est sheet.
B6: Step 3 GROWTH RATES (Sheet: Growth) | C6: Cells C6–C11 = Historical EPS data. Update if you have more recent annual reports. Cells C21–C22 = Net Profit and Equity from latest Balance Sheet for SGR calculation. Analyst forecasts in C28:C30 can be updated from Bloomberg/NSE analyst reports.
B7: Step 4 VALUATION (Sheet: Valuation) | C7: Cell C5 = Base EPS (update to latest year). Cell C15 = Current Market Price (enter today's price). All other cells are formula-driven and will update automatically.
B8: Step 5 SENSITIVITY (Sheet: Sensitivity) | C8: The sensitivity tables are hard-coded with the current base-case values. To update: change the growth rates in column B and P/E multiples in row 4. The IV calculations are direct formulas: Forward EPS × P/E.
B9: Step 6 FINANCIALS (Sheet: Financials) | C9: This sheet contains historical financial data sourced from Trent Annual Reports. Update with the latest quarterly or annual data as it becomes available.
